[2024-08-30T03:30:03.769+0000] {processor.py:186} INFO - Started process (PID=56) to work on /opt/airflow/dags/download_dag.py
[2024-08-30T03:30:03.770+0000] {processor.py:914} INFO - Processing file /opt/airflow/dags/download_dag.py for tasks to queue
[2024-08-30T03:30:03.772+0000] {logging_mixin.py:190} INFO - [2024-08-30T03:30:03.772+0000] {dagbag.py:587} INFO - Filling up the DagBag from /opt/airflow/dags/download_dag.py
[2024-08-30T03:30:04.143+0000] {logging_mixin.py:190} INFO - [2024-08-30T03:30:04.131+0000] {dagbag.py:386} ERROR - Failed to import: /opt/airflow/dags/download_dag.py
Traceback (most recent call last):
  File "/home/airflow/.local/lib/python3.12/site-packages/airflow/models/dagbag.py", line 382, in parse
    loader.exec_module(new_module)
  File "<frozen importlib._bootstrap_external>", line 995, in exec_module
  File "<frozen importlib._bootstrap>", line 488, in _call_with_frames_removed
  File "/opt/airflow/dags/download_dag.py", line 27, in <module>
    minio_client = Minio(
                   ^^^^^^
  File "/home/airflow/.local/lib/python3.12/site-packages/minio/api.py", line 153, in __init__
    ("https://" if secure else "http://") + endpoint,
    ~~~~~~~~~~~~~~~~~~~~~~~~~~~~~~~~~~~~~~^~~~~~~~~~
TypeError: can only concatenate str (not "NoneType") to str
[2024-08-30T03:30:04.145+0000] {processor.py:927} WARNING - No viable dags retrieved from /opt/airflow/dags/download_dag.py
[2024-08-30T03:30:04.160+0000] {processor.py:208} INFO - Processing /opt/airflow/dags/download_dag.py took 0.395 seconds
[2024-08-30T03:30:34.258+0000] {processor.py:186} INFO - Started process (PID=125) to work on /opt/airflow/dags/download_dag.py
[2024-08-30T03:30:34.260+0000] {processor.py:914} INFO - Processing file /opt/airflow/dags/download_dag.py for tasks to queue
[2024-08-30T03:30:34.262+0000] {logging_mixin.py:190} INFO - [2024-08-30T03:30:34.262+0000] {dagbag.py:587} INFO - Filling up the DagBag from /opt/airflow/dags/download_dag.py
[2024-08-30T03:30:34.450+0000] {logging_mixin.py:190} INFO - [2024-08-30T03:30:34.442+0000] {dagbag.py:386} ERROR - Failed to import: /opt/airflow/dags/download_dag.py
Traceback (most recent call last):
  File "/home/airflow/.local/lib/python3.12/site-packages/airflow/models/dagbag.py", line 382, in parse
    loader.exec_module(new_module)
  File "<frozen importlib._bootstrap_external>", line 995, in exec_module
  File "<frozen importlib._bootstrap>", line 488, in _call_with_frames_removed
  File "/opt/airflow/dags/download_dag.py", line 27, in <module>
    minio_client = Minio(
                   ^^^^^^
  File "/home/airflow/.local/lib/python3.12/site-packages/minio/api.py", line 153, in __init__
    ("https://" if secure else "http://") + endpoint,
    ~~~~~~~~~~~~~~~~~~~~~~~~~~~~~~~~~~~~~~^~~~~~~~~~
TypeError: can only concatenate str (not "NoneType") to str
[2024-08-30T03:30:34.453+0000] {processor.py:927} WARNING - No viable dags retrieved from /opt/airflow/dags/download_dag.py
[2024-08-30T03:30:34.471+0000] {processor.py:208} INFO - Processing /opt/airflow/dags/download_dag.py took 0.220 seconds
[2024-08-30T03:31:04.821+0000] {processor.py:186} INFO - Started process (PID=188) to work on /opt/airflow/dags/download_dag.py
[2024-08-30T03:31:04.823+0000] {processor.py:914} INFO - Processing file /opt/airflow/dags/download_dag.py for tasks to queue
[2024-08-30T03:31:04.825+0000] {logging_mixin.py:190} INFO - [2024-08-30T03:31:04.825+0000] {dagbag.py:587} INFO - Filling up the DagBag from /opt/airflow/dags/download_dag.py
[2024-08-30T03:31:05.002+0000] {logging_mixin.py:190} INFO - [2024-08-30T03:31:04.996+0000] {dagbag.py:386} ERROR - Failed to import: /opt/airflow/dags/download_dag.py
Traceback (most recent call last):
  File "/home/airflow/.local/lib/python3.12/site-packages/airflow/models/dagbag.py", line 382, in parse
    loader.exec_module(new_module)
  File "<frozen importlib._bootstrap_external>", line 995, in exec_module
  File "<frozen importlib._bootstrap>", line 488, in _call_with_frames_removed
  File "/opt/airflow/dags/download_dag.py", line 27, in <module>
    minio_client = Minio(
                   ^^^^^^
  File "/home/airflow/.local/lib/python3.12/site-packages/minio/api.py", line 153, in __init__
    ("https://" if secure else "http://") + endpoint,
    ~~~~~~~~~~~~~~~~~~~~~~~~~~~~~~~~~~~~~~^~~~~~~~~~
TypeError: can only concatenate str (not "NoneType") to str
[2024-08-30T03:31:05.005+0000] {processor.py:927} WARNING - No viable dags retrieved from /opt/airflow/dags/download_dag.py
[2024-08-30T03:31:05.021+0000] {processor.py:208} INFO - Processing /opt/airflow/dags/download_dag.py took 0.205 seconds
[2024-08-30T03:31:35.617+0000] {processor.py:186} INFO - Started process (PID=251) to work on /opt/airflow/dags/download_dag.py
[2024-08-30T03:31:35.619+0000] {processor.py:914} INFO - Processing file /opt/airflow/dags/download_dag.py for tasks to queue
[2024-08-30T03:31:35.622+0000] {logging_mixin.py:190} INFO - [2024-08-30T03:31:35.622+0000] {dagbag.py:587} INFO - Filling up the DagBag from /opt/airflow/dags/download_dag.py
[2024-08-30T03:31:35.794+0000] {logging_mixin.py:190} INFO - [2024-08-30T03:31:35.786+0000] {dagbag.py:386} ERROR - Failed to import: /opt/airflow/dags/download_dag.py
Traceback (most recent call last):
  File "/home/airflow/.local/lib/python3.12/site-packages/airflow/models/dagbag.py", line 382, in parse
    loader.exec_module(new_module)
  File "<frozen importlib._bootstrap_external>", line 995, in exec_module
  File "<frozen importlib._bootstrap>", line 488, in _call_with_frames_removed
  File "/opt/airflow/dags/download_dag.py", line 27, in <module>
    minio_client = Minio(
                   ^^^^^^
  File "/home/airflow/.local/lib/python3.12/site-packages/minio/api.py", line 153, in __init__
    ("https://" if secure else "http://") + endpoint,
    ~~~~~~~~~~~~~~~~~~~~~~~~~~~~~~~~~~~~~~^~~~~~~~~~
TypeError: can only concatenate str (not "NoneType") to str
[2024-08-30T03:31:35.796+0000] {processor.py:927} WARNING - No viable dags retrieved from /opt/airflow/dags/download_dag.py
[2024-08-30T03:31:35.825+0000] {processor.py:208} INFO - Processing /opt/airflow/dags/download_dag.py took 0.214 seconds
[2024-08-30T03:32:06.379+0000] {processor.py:186} INFO - Started process (PID=314) to work on /opt/airflow/dags/download_dag.py
[2024-08-30T03:32:06.388+0000] {processor.py:914} INFO - Processing file /opt/airflow/dags/download_dag.py for tasks to queue
[2024-08-30T03:32:06.398+0000] {logging_mixin.py:190} INFO - [2024-08-30T03:32:06.398+0000] {dagbag.py:587} INFO - Filling up the DagBag from /opt/airflow/dags/download_dag.py
[2024-08-30T03:32:06.845+0000] {logging_mixin.py:190} INFO - [2024-08-30T03:32:06.799+0000] {dagbag.py:386} ERROR - Failed to import: /opt/airflow/dags/download_dag.py
Traceback (most recent call last):
  File "/home/airflow/.local/lib/python3.12/site-packages/airflow/models/dagbag.py", line 382, in parse
    loader.exec_module(new_module)
  File "<frozen importlib._bootstrap_external>", line 995, in exec_module
  File "<frozen importlib._bootstrap>", line 488, in _call_with_frames_removed
  File "/opt/airflow/dags/download_dag.py", line 27, in <module>
    minio_client = Minio(
                   ^^^^^^
  File "/home/airflow/.local/lib/python3.12/site-packages/minio/api.py", line 153, in __init__
    ("https://" if secure else "http://") + endpoint,
    ~~~~~~~~~~~~~~~~~~~~~~~~~~~~~~~~~~~~~~^~~~~~~~~~
TypeError: can only concatenate str (not "NoneType") to str
[2024-08-30T03:32:06.851+0000] {processor.py:927} WARNING - No viable dags retrieved from /opt/airflow/dags/download_dag.py
[2024-08-30T03:32:06.893+0000] {processor.py:208} INFO - Processing /opt/airflow/dags/download_dag.py took 0.523 seconds
[2024-08-30T03:32:37.310+0000] {processor.py:186} INFO - Started process (PID=377) to work on /opt/airflow/dags/download_dag.py
[2024-08-30T03:32:37.311+0000] {processor.py:914} INFO - Processing file /opt/airflow/dags/download_dag.py for tasks to queue
[2024-08-30T03:32:37.313+0000] {logging_mixin.py:190} INFO - [2024-08-30T03:32:37.312+0000] {dagbag.py:587} INFO - Filling up the DagBag from /opt/airflow/dags/download_dag.py
[2024-08-30T03:32:37.699+0000] {logging_mixin.py:190} INFO - [2024-08-30T03:32:37.649+0000] {dagbag.py:386} ERROR - Failed to import: /opt/airflow/dags/download_dag.py
Traceback (most recent call last):
  File "/home/airflow/.local/lib/python3.12/site-packages/airflow/models/dagbag.py", line 382, in parse
    loader.exec_module(new_module)
  File "<frozen importlib._bootstrap_external>", line 995, in exec_module
  File "<frozen importlib._bootstrap>", line 488, in _call_with_frames_removed
  File "/opt/airflow/dags/download_dag.py", line 27, in <module>
    minio_client = Minio(
                   ^^^^^^
  File "/home/airflow/.local/lib/python3.12/site-packages/minio/api.py", line 153, in __init__
    ("https://" if secure else "http://") + endpoint,
    ~~~~~~~~~~~~~~~~~~~~~~~~~~~~~~~~~~~~~~^~~~~~~~~~
TypeError: can only concatenate str (not "NoneType") to str
[2024-08-30T03:32:37.701+0000] {processor.py:927} WARNING - No viable dags retrieved from /opt/airflow/dags/download_dag.py
[2024-08-30T03:32:37.740+0000] {processor.py:208} INFO - Processing /opt/airflow/dags/download_dag.py took 0.435 seconds
[2024-08-30T03:33:08.275+0000] {processor.py:186} INFO - Started process (PID=440) to work on /opt/airflow/dags/download_dag.py
[2024-08-30T03:33:08.276+0000] {processor.py:914} INFO - Processing file /opt/airflow/dags/download_dag.py for tasks to queue
[2024-08-30T03:33:08.278+0000] {logging_mixin.py:190} INFO - [2024-08-30T03:33:08.277+0000] {dagbag.py:587} INFO - Filling up the DagBag from /opt/airflow/dags/download_dag.py
[2024-08-30T03:33:08.477+0000] {logging_mixin.py:190} INFO - [2024-08-30T03:33:08.460+0000] {dagbag.py:386} ERROR - Failed to import: /opt/airflow/dags/download_dag.py
Traceback (most recent call last):
  File "/home/airflow/.local/lib/python3.12/site-packages/airflow/models/dagbag.py", line 382, in parse
    loader.exec_module(new_module)
  File "<frozen importlib._bootstrap_external>", line 995, in exec_module
  File "<frozen importlib._bootstrap>", line 488, in _call_with_frames_removed
  File "/opt/airflow/dags/download_dag.py", line 27, in <module>
    minio_client = Minio(
                   ^^^^^^
  File "/home/airflow/.local/lib/python3.12/site-packages/minio/api.py", line 153, in __init__
    ("https://" if secure else "http://") + endpoint,
    ~~~~~~~~~~~~~~~~~~~~~~~~~~~~~~~~~~~~~~^~~~~~~~~~
TypeError: can only concatenate str (not "NoneType") to str
[2024-08-30T03:33:08.479+0000] {processor.py:927} WARNING - No viable dags retrieved from /opt/airflow/dags/download_dag.py
[2024-08-30T03:33:08.497+0000] {processor.py:208} INFO - Processing /opt/airflow/dags/download_dag.py took 0.226 seconds
[2024-08-30T03:33:39.339+0000] {processor.py:186} INFO - Started process (PID=503) to work on /opt/airflow/dags/download_dag.py
[2024-08-30T03:33:39.340+0000] {processor.py:914} INFO - Processing file /opt/airflow/dags/download_dag.py for tasks to queue
[2024-08-30T03:33:39.342+0000] {logging_mixin.py:190} INFO - [2024-08-30T03:33:39.342+0000] {dagbag.py:587} INFO - Filling up the DagBag from /opt/airflow/dags/download_dag.py
[2024-08-30T03:33:39.549+0000] {logging_mixin.py:190} INFO - [2024-08-30T03:33:39.504+0000] {dagbag.py:386} ERROR - Failed to import: /opt/airflow/dags/download_dag.py
Traceback (most recent call last):
  File "/home/airflow/.local/lib/python3.12/site-packages/airflow/models/dagbag.py", line 382, in parse
    loader.exec_module(new_module)
  File "<frozen importlib._bootstrap_external>", line 995, in exec_module
  File "<frozen importlib._bootstrap>", line 488, in _call_with_frames_removed
  File "/opt/airflow/dags/download_dag.py", line 27, in <module>
    minio_client = Minio(
                   ^^^^^^
  File "/home/airflow/.local/lib/python3.12/site-packages/minio/api.py", line 153, in __init__
    ("https://" if secure else "http://") + endpoint,
    ~~~~~~~~~~~~~~~~~~~~~~~~~~~~~~~~~~~~~~^~~~~~~~~~
TypeError: can only concatenate str (not "NoneType") to str
[2024-08-30T03:33:39.566+0000] {processor.py:927} WARNING - No viable dags retrieved from /opt/airflow/dags/download_dag.py
[2024-08-30T03:33:39.584+0000] {processor.py:208} INFO - Processing /opt/airflow/dags/download_dag.py took 0.251 seconds
[2024-08-30T03:34:10.020+0000] {processor.py:186} INFO - Started process (PID=566) to work on /opt/airflow/dags/download_dag.py
[2024-08-30T03:34:10.021+0000] {processor.py:914} INFO - Processing file /opt/airflow/dags/download_dag.py for tasks to queue
[2024-08-30T03:34:10.023+0000] {logging_mixin.py:190} INFO - [2024-08-30T03:34:10.023+0000] {dagbag.py:587} INFO - Filling up the DagBag from /opt/airflow/dags/download_dag.py
[2024-08-30T03:34:10.189+0000] {logging_mixin.py:190} INFO - [2024-08-30T03:34:10.183+0000] {dagbag.py:386} ERROR - Failed to import: /opt/airflow/dags/download_dag.py
Traceback (most recent call last):
  File "/home/airflow/.local/lib/python3.12/site-packages/airflow/models/dagbag.py", line 382, in parse
    loader.exec_module(new_module)
  File "<frozen importlib._bootstrap_external>", line 995, in exec_module
  File "<frozen importlib._bootstrap>", line 488, in _call_with_frames_removed
  File "/opt/airflow/dags/download_dag.py", line 27, in <module>
    minio_client = Minio(
                   ^^^^^^
  File "/home/airflow/.local/lib/python3.12/site-packages/minio/api.py", line 153, in __init__
    ("https://" if secure else "http://") + endpoint,
    ~~~~~~~~~~~~~~~~~~~~~~~~~~~~~~~~~~~~~~^~~~~~~~~~
TypeError: can only concatenate str (not "NoneType") to str
[2024-08-30T03:34:10.192+0000] {processor.py:927} WARNING - No viable dags retrieved from /opt/airflow/dags/download_dag.py
[2024-08-30T03:34:10.207+0000] {processor.py:208} INFO - Processing /opt/airflow/dags/download_dag.py took 0.192 seconds
[2024-08-30T03:34:40.776+0000] {processor.py:186} INFO - Started process (PID=629) to work on /opt/airflow/dags/download_dag.py
[2024-08-30T03:34:40.778+0000] {processor.py:914} INFO - Processing file /opt/airflow/dags/download_dag.py for tasks to queue
[2024-08-30T03:34:40.780+0000] {logging_mixin.py:190} INFO - [2024-08-30T03:34:40.779+0000] {dagbag.py:587} INFO - Filling up the DagBag from /opt/airflow/dags/download_dag.py
[2024-08-30T03:34:40.942+0000] {logging_mixin.py:190} INFO - [2024-08-30T03:34:40.936+0000] {dagbag.py:386} ERROR - Failed to import: /opt/airflow/dags/download_dag.py
Traceback (most recent call last):
  File "/home/airflow/.local/lib/python3.12/site-packages/airflow/models/dagbag.py", line 382, in parse
    loader.exec_module(new_module)
  File "<frozen importlib._bootstrap_external>", line 995, in exec_module
  File "<frozen importlib._bootstrap>", line 488, in _call_with_frames_removed
  File "/opt/airflow/dags/download_dag.py", line 27, in <module>
    minio_client = Minio(
                   ^^^^^^
  File "/home/airflow/.local/lib/python3.12/site-packages/minio/api.py", line 153, in __init__
    ("https://" if secure else "http://") + endpoint,
    ~~~~~~~~~~~~~~~~~~~~~~~~~~~~~~~~~~~~~~^~~~~~~~~~
TypeError: can only concatenate str (not "NoneType") to str
[2024-08-30T03:34:40.943+0000] {processor.py:927} WARNING - No viable dags retrieved from /opt/airflow/dags/download_dag.py
[2024-08-30T03:34:40.959+0000] {processor.py:208} INFO - Processing /opt/airflow/dags/download_dag.py took 0.187 seconds
[2024-08-30T03:35:11.610+0000] {processor.py:186} INFO - Started process (PID=692) to work on /opt/airflow/dags/download_dag.py
[2024-08-30T03:35:11.611+0000] {processor.py:914} INFO - Processing file /opt/airflow/dags/download_dag.py for tasks to queue
[2024-08-30T03:35:11.613+0000] {logging_mixin.py:190} INFO - [2024-08-30T03:35:11.613+0000] {dagbag.py:587} INFO - Filling up the DagBag from /opt/airflow/dags/download_dag.py
[2024-08-30T03:35:11.849+0000] {logging_mixin.py:190} INFO - [2024-08-30T03:35:11.810+0000] {dagbag.py:386} ERROR - Failed to import: /opt/airflow/dags/download_dag.py
Traceback (most recent call last):
  File "/home/airflow/.local/lib/python3.12/site-packages/airflow/models/dagbag.py", line 382, in parse
    loader.exec_module(new_module)
  File "<frozen importlib._bootstrap_external>", line 995, in exec_module
  File "<frozen importlib._bootstrap>", line 488, in _call_with_frames_removed
  File "/opt/airflow/dags/download_dag.py", line 27, in <module>
    minio_client = Minio(
                   ^^^^^^
  File "/home/airflow/.local/lib/python3.12/site-packages/minio/api.py", line 153, in __init__
    ("https://" if secure else "http://") + endpoint,
    ~~~~~~~~~~~~~~~~~~~~~~~~~~~~~~~~~~~~~~^~~~~~~~~~
TypeError: can only concatenate str (not "NoneType") to str
[2024-08-30T03:35:11.854+0000] {processor.py:927} WARNING - No viable dags retrieved from /opt/airflow/dags/download_dag.py
[2024-08-30T03:35:11.883+0000] {processor.py:208} INFO - Processing /opt/airflow/dags/download_dag.py took 0.277 seconds
[2024-08-30T03:35:42.018+0000] {processor.py:186} INFO - Started process (PID=755) to work on /opt/airflow/dags/download_dag.py
[2024-08-30T03:35:42.019+0000] {processor.py:914} INFO - Processing file /opt/airflow/dags/download_dag.py for tasks to queue
[2024-08-30T03:35:42.021+0000] {logging_mixin.py:190} INFO - [2024-08-30T03:35:42.021+0000] {dagbag.py:587} INFO - Filling up the DagBag from /opt/airflow/dags/download_dag.py
[2024-08-30T03:35:42.173+0000] {logging_mixin.py:190} INFO - [2024-08-30T03:35:42.166+0000] {dagbag.py:386} ERROR - Failed to import: /opt/airflow/dags/download_dag.py
Traceback (most recent call last):
  File "/home/airflow/.local/lib/python3.12/site-packages/airflow/models/dagbag.py", line 382, in parse
    loader.exec_module(new_module)
  File "<frozen importlib._bootstrap_external>", line 995, in exec_module
  File "<frozen importlib._bootstrap>", line 488, in _call_with_frames_removed
  File "/opt/airflow/dags/download_dag.py", line 27, in <module>
    minio_client = Minio(
                   ^^^^^^
  File "/home/airflow/.local/lib/python3.12/site-packages/minio/api.py", line 153, in __init__
    ("https://" if secure else "http://") + endpoint,
    ~~~~~~~~~~~~~~~~~~~~~~~~~~~~~~~~~~~~~~^~~~~~~~~~
TypeError: can only concatenate str (not "NoneType") to str
[2024-08-30T03:35:42.175+0000] {processor.py:927} WARNING - No viable dags retrieved from /opt/airflow/dags/download_dag.py
[2024-08-30T03:35:42.190+0000] {processor.py:208} INFO - Processing /opt/airflow/dags/download_dag.py took 0.177 seconds
[2024-08-30T03:36:12.977+0000] {processor.py:186} INFO - Started process (PID=818) to work on /opt/airflow/dags/download_dag.py
[2024-08-30T03:36:12.978+0000] {processor.py:914} INFO - Processing file /opt/airflow/dags/download_dag.py for tasks to queue
[2024-08-30T03:36:12.981+0000] {logging_mixin.py:190} INFO - [2024-08-30T03:36:12.981+0000] {dagbag.py:587} INFO - Filling up the DagBag from /opt/airflow/dags/download_dag.py
[2024-08-30T03:36:13.131+0000] {logging_mixin.py:190} INFO - [2024-08-30T03:36:13.124+0000] {dagbag.py:386} ERROR - Failed to import: /opt/airflow/dags/download_dag.py
Traceback (most recent call last):
  File "/home/airflow/.local/lib/python3.12/site-packages/airflow/models/dagbag.py", line 382, in parse
    loader.exec_module(new_module)
  File "<frozen importlib._bootstrap_external>", line 995, in exec_module
  File "<frozen importlib._bootstrap>", line 488, in _call_with_frames_removed
  File "/opt/airflow/dags/download_dag.py", line 27, in <module>
    minio_client = Minio(
                   ^^^^^^
  File "/home/airflow/.local/lib/python3.12/site-packages/minio/api.py", line 153, in __init__
    ("https://" if secure else "http://") + endpoint,
    ~~~~~~~~~~~~~~~~~~~~~~~~~~~~~~~~~~~~~~^~~~~~~~~~
TypeError: can only concatenate str (not "NoneType") to str
[2024-08-30T03:36:13.133+0000] {processor.py:927} WARNING - No viable dags retrieved from /opt/airflow/dags/download_dag.py
[2024-08-30T03:36:13.146+0000] {processor.py:208} INFO - Processing /opt/airflow/dags/download_dag.py took 0.174 seconds
[2024-08-30T03:36:17.175+0000] {processor.py:186} INFO - Started process (PID=848) to work on /opt/airflow/dags/download_dag.py
[2024-08-30T03:36:17.176+0000] {processor.py:914} INFO - Processing file /opt/airflow/dags/download_dag.py for tasks to queue
[2024-08-30T03:36:17.179+0000] {logging_mixin.py:190} INFO - [2024-08-30T03:36:17.178+0000] {dagbag.py:587} INFO - Filling up the DagBag from /opt/airflow/dags/download_dag.py
[2024-08-30T03:36:17.347+0000] {logging_mixin.py:190} INFO - [2024-08-30T03:36:17.338+0000] {dagbag.py:386} ERROR - Failed to import: /opt/airflow/dags/download_dag.py
Traceback (most recent call last):
  File "/home/airflow/.local/lib/python3.12/site-packages/airflow/models/dagbag.py", line 382, in parse
    loader.exec_module(new_module)
  File "<frozen importlib._bootstrap_external>", line 995, in exec_module
  File "<frozen importlib._bootstrap>", line 488, in _call_with_frames_removed
  File "/opt/airflow/dags/download_dag.py", line 29, in <module>
    minio_client = Minio(
                   ^^^^^^
  File "/home/airflow/.local/lib/python3.12/site-packages/minio/api.py", line 153, in __init__
    ("https://" if secure else "http://") + endpoint,
    ~~~~~~~~~~~~~~~~~~~~~~~~~~~~~~~~~~~~~~^~~~~~~~~~
TypeError: can only concatenate str (not "NoneType") to str
[2024-08-30T03:36:17.350+0000] {processor.py:927} WARNING - No viable dags retrieved from /opt/airflow/dags/download_dag.py
[2024-08-30T03:36:17.366+0000] {processor.py:208} INFO - Processing /opt/airflow/dags/download_dag.py took 0.197 seconds
[2024-08-30T03:37:27.766+0000] {processor.py:186} INFO - Started process (PID=61) to work on /opt/airflow/dags/download_dag.py
[2024-08-30T03:37:27.769+0000] {processor.py:914} INFO - Processing file /opt/airflow/dags/download_dag.py for tasks to queue
[2024-08-30T03:37:27.775+0000] {logging_mixin.py:190} INFO - [2024-08-30T03:37:27.775+0000] {dagbag.py:587} INFO - Filling up the DagBag from /opt/airflow/dags/download_dag.py
[2024-08-30T03:37:28.089+0000] {logging_mixin.py:190} INFO - [2024-08-30T03:37:28.082+0000] {dagbag.py:386} ERROR - Failed to import: /opt/airflow/dags/download_dag.py
Traceback (most recent call last):
  File "/home/airflow/.local/lib/python3.12/site-packages/airflow/models/dagbag.py", line 382, in parse
    loader.exec_module(new_module)
  File "<frozen importlib._bootstrap_external>", line 995, in exec_module
  File "<frozen importlib._bootstrap>", line 488, in _call_with_frames_removed
  File "/opt/airflow/dags/download_dag.py", line 29, in <module>
    minio_client = Minio(
                   ^^^^^^
  File "/home/airflow/.local/lib/python3.12/site-packages/minio/api.py", line 153, in __init__
    ("https://" if secure else "http://") + endpoint,
    ~~~~~~~~~~~~~~~~~~~~~~~~~~~~~~~~~~~~~~^~~~~~~~~~
TypeError: can only concatenate str (not "NoneType") to str
[2024-08-30T03:37:28.091+0000] {processor.py:927} WARNING - No viable dags retrieved from /opt/airflow/dags/download_dag.py
[2024-08-30T03:37:28.105+0000] {processor.py:208} INFO - Processing /opt/airflow/dags/download_dag.py took 0.343 seconds
[2024-08-30T03:37:58.671+0000] {processor.py:186} INFO - Started process (PID=124) to work on /opt/airflow/dags/download_dag.py
[2024-08-30T03:37:58.672+0000] {processor.py:914} INFO - Processing file /opt/airflow/dags/download_dag.py for tasks to queue
[2024-08-30T03:37:58.675+0000] {logging_mixin.py:190} INFO - [2024-08-30T03:37:58.674+0000] {dagbag.py:587} INFO - Filling up the DagBag from /opt/airflow/dags/download_dag.py
[2024-08-30T03:37:58.827+0000] {logging_mixin.py:190} INFO - [2024-08-30T03:37:58.820+0000] {dagbag.py:386} ERROR - Failed to import: /opt/airflow/dags/download_dag.py
Traceback (most recent call last):
  File "/home/airflow/.local/lib/python3.12/site-packages/airflow/models/dagbag.py", line 382, in parse
    loader.exec_module(new_module)
  File "<frozen importlib._bootstrap_external>", line 995, in exec_module
  File "<frozen importlib._bootstrap>", line 488, in _call_with_frames_removed
  File "/opt/airflow/dags/download_dag.py", line 29, in <module>
    minio_client = Minio(
                   ^^^^^^
  File "/home/airflow/.local/lib/python3.12/site-packages/minio/api.py", line 153, in __init__
    ("https://" if secure else "http://") + endpoint,
    ~~~~~~~~~~~~~~~~~~~~~~~~~~~~~~~~~~~~~~^~~~~~~~~~
TypeError: can only concatenate str (not "NoneType") to str
[2024-08-30T03:37:58.829+0000] {processor.py:927} WARNING - No viable dags retrieved from /opt/airflow/dags/download_dag.py
[2024-08-30T03:37:58.845+0000] {processor.py:208} INFO - Processing /opt/airflow/dags/download_dag.py took 0.178 seconds
[2024-08-30T03:38:28.903+0000] {processor.py:186} INFO - Started process (PID=188) to work on /opt/airflow/dags/download_dag.py
[2024-08-30T03:38:28.904+0000] {processor.py:914} INFO - Processing file /opt/airflow/dags/download_dag.py for tasks to queue
[2024-08-30T03:38:28.906+0000] {logging_mixin.py:190} INFO - [2024-08-30T03:38:28.906+0000] {dagbag.py:587} INFO - Filling up the DagBag from /opt/airflow/dags/download_dag.py
[2024-08-30T03:38:29.065+0000] {logging_mixin.py:190} INFO - [2024-08-30T03:38:29.055+0000] {dagbag.py:386} ERROR - Failed to import: /opt/airflow/dags/download_dag.py
Traceback (most recent call last):
  File "/home/airflow/.local/lib/python3.12/site-packages/airflow/models/dagbag.py", line 382, in parse
    loader.exec_module(new_module)
  File "<frozen importlib._bootstrap_external>", line 995, in exec_module
  File "<frozen importlib._bootstrap>", line 488, in _call_with_frames_removed
  File "/opt/airflow/dags/download_dag.py", line 29, in <module>
    minio_client = Minio(
                   ^^^^^^
  File "/home/airflow/.local/lib/python3.12/site-packages/minio/api.py", line 153, in __init__
    ("https://" if secure else "http://") + endpoint,
    ~~~~~~~~~~~~~~~~~~~~~~~~~~~~~~~~~~~~~~^~~~~~~~~~
TypeError: can only concatenate str (not "NoneType") to str
[2024-08-30T03:38:29.068+0000] {processor.py:927} WARNING - No viable dags retrieved from /opt/airflow/dags/download_dag.py
[2024-08-30T03:38:29.084+0000] {processor.py:208} INFO - Processing /opt/airflow/dags/download_dag.py took 0.185 seconds
[2024-08-30T03:38:59.534+0000] {processor.py:186} INFO - Started process (PID=250) to work on /opt/airflow/dags/download_dag.py
[2024-08-30T03:38:59.535+0000] {processor.py:914} INFO - Processing file /opt/airflow/dags/download_dag.py for tasks to queue
[2024-08-30T03:38:59.537+0000] {logging_mixin.py:190} INFO - [2024-08-30T03:38:59.537+0000] {dagbag.py:587} INFO - Filling up the DagBag from /opt/airflow/dags/download_dag.py
[2024-08-30T03:38:59.680+0000] {logging_mixin.py:190} INFO - [2024-08-30T03:38:59.676+0000] {dagbag.py:386} ERROR - Failed to import: /opt/airflow/dags/download_dag.py
Traceback (most recent call last):
  File "/home/airflow/.local/lib/python3.12/site-packages/airflow/models/dagbag.py", line 382, in parse
    loader.exec_module(new_module)
  File "<frozen importlib._bootstrap_external>", line 995, in exec_module
  File "<frozen importlib._bootstrap>", line 488, in _call_with_frames_removed
  File "/opt/airflow/dags/download_dag.py", line 29, in <module>
    minio_client = Minio(
                   ^^^^^^
  File "/home/airflow/.local/lib/python3.12/site-packages/minio/api.py", line 153, in __init__
    ("https://" if secure else "http://") + endpoint,
    ~~~~~~~~~~~~~~~~~~~~~~~~~~~~~~~~~~~~~~^~~~~~~~~~
TypeError: can only concatenate str (not "NoneType") to str
[2024-08-30T03:38:59.681+0000] {processor.py:927} WARNING - No viable dags retrieved from /opt/airflow/dags/download_dag.py
[2024-08-30T03:38:59.696+0000] {processor.py:208} INFO - Processing /opt/airflow/dags/download_dag.py took 0.166 seconds
[2024-08-30T03:39:30.348+0000] {processor.py:186} INFO - Started process (PID=313) to work on /opt/airflow/dags/download_dag.py
[2024-08-30T03:39:30.350+0000] {processor.py:914} INFO - Processing file /opt/airflow/dags/download_dag.py for tasks to queue
[2024-08-30T03:39:30.352+0000] {logging_mixin.py:190} INFO - [2024-08-30T03:39:30.351+0000] {dagbag.py:587} INFO - Filling up the DagBag from /opt/airflow/dags/download_dag.py
[2024-08-30T03:39:30.515+0000] {logging_mixin.py:190} INFO - [2024-08-30T03:39:30.510+0000] {dagbag.py:386} ERROR - Failed to import: /opt/airflow/dags/download_dag.py
Traceback (most recent call last):
  File "/home/airflow/.local/lib/python3.12/site-packages/airflow/models/dagbag.py", line 382, in parse
    loader.exec_module(new_module)
  File "<frozen importlib._bootstrap_external>", line 995, in exec_module
  File "<frozen importlib._bootstrap>", line 488, in _call_with_frames_removed
  File "/opt/airflow/dags/download_dag.py", line 29, in <module>
    minio_client = Minio(
                   ^^^^^^
  File "/home/airflow/.local/lib/python3.12/site-packages/minio/api.py", line 153, in __init__
    ("https://" if secure else "http://") + endpoint,
    ~~~~~~~~~~~~~~~~~~~~~~~~~~~~~~~~~~~~~~^~~~~~~~~~
TypeError: can only concatenate str (not "NoneType") to str
[2024-08-30T03:39:30.517+0000] {processor.py:927} WARNING - No viable dags retrieved from /opt/airflow/dags/download_dag.py
[2024-08-30T03:39:30.532+0000] {processor.py:208} INFO - Processing /opt/airflow/dags/download_dag.py took 0.188 seconds
[2024-08-30T03:39:55.914+0000] {processor.py:186} INFO - Started process (PID=376) to work on /opt/airflow/dags/download_dag.py
[2024-08-30T03:39:55.915+0000] {processor.py:914} INFO - Processing file /opt/airflow/dags/download_dag.py for tasks to queue
[2024-08-30T03:39:55.917+0000] {logging_mixin.py:190} INFO - [2024-08-30T03:39:55.917+0000] {dagbag.py:587} INFO - Filling up the DagBag from /opt/airflow/dags/download_dag.py
[2024-08-30T03:39:55.931+0000] {logging_mixin.py:190} INFO - [2024-08-30T03:39:55.930+0000] {dagbag.py:386} ERROR - Failed to import: /opt/airflow/dags/download_dag.py
Traceback (most recent call last):
  File "/home/airflow/.local/lib/python3.12/site-packages/airflow/models/dagbag.py", line 382, in parse
    loader.exec_module(new_module)
  File "<frozen importlib._bootstrap_external>", line 991, in exec_module
  File "<frozen importlib._bootstrap_external>", line 1129, in get_code
  File "<frozen importlib._bootstrap_external>", line 1059, in source_to_code
  File "<frozen importlib._bootstrap>", line 488, in _call_with_frames_removed
  File "/opt/airflow/dags/download_dag.py", line 14
    env_path = 'C:\Data\BK HK241\Thesis\New folder\Test-Kafka\airflow\.env'
               ^^^^^^^^^^^^^^^^^^^^^^^^^^^^^^^^^^^^^^^^^^^^^^^^^^^^^^^^^^^^
SyntaxError: (unicode error) 'unicodeescape' codec can't decode bytes in position 23-24: malformed \N character escape
[2024-08-30T03:39:55.932+0000] {processor.py:927} WARNING - No viable dags retrieved from /opt/airflow/dags/download_dag.py
[2024-08-30T03:39:55.958+0000] {processor.py:208} INFO - Processing /opt/airflow/dags/download_dag.py took 0.047 seconds
[2024-08-30T03:40:26.468+0000] {processor.py:186} INFO - Started process (PID=439) to work on /opt/airflow/dags/download_dag.py
[2024-08-30T03:40:26.469+0000] {processor.py:914} INFO - Processing file /opt/airflow/dags/download_dag.py for tasks to queue
[2024-08-30T03:40:26.471+0000] {logging_mixin.py:190} INFO - [2024-08-30T03:40:26.470+0000] {dagbag.py:587} INFO - Filling up the DagBag from /opt/airflow/dags/download_dag.py
[2024-08-30T03:40:26.481+0000] {logging_mixin.py:190} INFO - [2024-08-30T03:40:26.481+0000] {dagbag.py:386} ERROR - Failed to import: /opt/airflow/dags/download_dag.py
Traceback (most recent call last):
  File "/home/airflow/.local/lib/python3.12/site-packages/airflow/models/dagbag.py", line 382, in parse
    loader.exec_module(new_module)
  File "<frozen importlib._bootstrap_external>", line 991, in exec_module
  File "<frozen importlib._bootstrap_external>", line 1129, in get_code
  File "<frozen importlib._bootstrap_external>", line 1059, in source_to_code
  File "<frozen importlib._bootstrap>", line 488, in _call_with_frames_removed
  File "/opt/airflow/dags/download_dag.py", line 14
    env_path = 'C:\Data\BK HK241\Thesis\New folder\Test-Kafka\airflow\.env'
               ^^^^^^^^^^^^^^^^^^^^^^^^^^^^^^^^^^^^^^^^^^^^^^^^^^^^^^^^^^^^
SyntaxError: (unicode error) 'unicodeescape' codec can't decode bytes in position 23-24: malformed \N character escape
[2024-08-30T03:40:26.482+0000] {processor.py:927} WARNING - No viable dags retrieved from /opt/airflow/dags/download_dag.py
[2024-08-30T03:40:26.499+0000] {processor.py:208} INFO - Processing /opt/airflow/dags/download_dag.py took 0.035 seconds
[2024-08-30T03:40:34.981+0000] {processor.py:186} INFO - Started process (PID=485) to work on /opt/airflow/dags/download_dag.py
[2024-08-30T03:40:34.982+0000] {processor.py:914} INFO - Processing file /opt/airflow/dags/download_dag.py for tasks to queue
[2024-08-30T03:40:34.983+0000] {logging_mixin.py:190} INFO - [2024-08-30T03:40:34.983+0000] {dagbag.py:587} INFO - Filling up the DagBag from /opt/airflow/dags/download_dag.py
[2024-08-30T03:40:35.156+0000] {logging_mixin.py:190} INFO - [2024-08-30T03:40:35.151+0000] {dagbag.py:386} ERROR - Failed to import: /opt/airflow/dags/download_dag.py
Traceback (most recent call last):
  File "/home/airflow/.local/lib/python3.12/site-packages/airflow/models/dagbag.py", line 382, in parse
    loader.exec_module(new_module)
  File "<frozen importlib._bootstrap_external>", line 995, in exec_module
  File "<frozen importlib._bootstrap>", line 488, in _call_with_frames_removed
  File "/opt/airflow/dags/download_dag.py", line 29, in <module>
    minio_client = Minio(
                   ^^^^^^
  File "/home/airflow/.local/lib/python3.12/site-packages/minio/api.py", line 153, in __init__
    ("https://" if secure else "http://") + endpoint,
    ~~~~~~~~~~~~~~~~~~~~~~~~~~~~~~~~~~~~~~^~~~~~~~~~
TypeError: can only concatenate str (not "NoneType") to str
[2024-08-30T03:40:35.158+0000] {processor.py:927} WARNING - No viable dags retrieved from /opt/airflow/dags/download_dag.py
[2024-08-30T03:40:35.174+0000] {processor.py:208} INFO - Processing /opt/airflow/dags/download_dag.py took 0.199 seconds
[2024-08-30T03:41:06.119+0000] {processor.py:186} INFO - Started process (PID=548) to work on /opt/airflow/dags/download_dag.py
[2024-08-30T03:41:06.120+0000] {processor.py:914} INFO - Processing file /opt/airflow/dags/download_dag.py for tasks to queue
[2024-08-30T03:41:06.127+0000] {logging_mixin.py:190} INFO - [2024-08-30T03:41:06.127+0000] {dagbag.py:587} INFO - Filling up the DagBag from /opt/airflow/dags/download_dag.py
[2024-08-30T03:41:06.277+0000] {logging_mixin.py:190} INFO - [2024-08-30T03:41:06.270+0000] {dagbag.py:386} ERROR - Failed to import: /opt/airflow/dags/download_dag.py
Traceback (most recent call last):
  File "/home/airflow/.local/lib/python3.12/site-packages/airflow/models/dagbag.py", line 382, in parse
    loader.exec_module(new_module)
  File "<frozen importlib._bootstrap_external>", line 995, in exec_module
  File "<frozen importlib._bootstrap>", line 488, in _call_with_frames_removed
  File "/opt/airflow/dags/download_dag.py", line 29, in <module>
    minio_client = Minio(
                   ^^^^^^
  File "/home/airflow/.local/lib/python3.12/site-packages/minio/api.py", line 153, in __init__
    ("https://" if secure else "http://") + endpoint,
    ~~~~~~~~~~~~~~~~~~~~~~~~~~~~~~~~~~~~~~^~~~~~~~~~
TypeError: can only concatenate str (not "NoneType") to str
[2024-08-30T03:41:06.279+0000] {processor.py:927} WARNING - No viable dags retrieved from /opt/airflow/dags/download_dag.py
[2024-08-30T03:41:06.296+0000] {processor.py:208} INFO - Processing /opt/airflow/dags/download_dag.py took 0.181 seconds
[2024-08-30T03:41:36.496+0000] {processor.py:186} INFO - Started process (PID=607) to work on /opt/airflow/dags/download_dag.py
[2024-08-30T03:41:36.497+0000] {processor.py:914} INFO - Processing file /opt/airflow/dags/download_dag.py for tasks to queue
[2024-08-30T03:41:36.499+0000] {logging_mixin.py:190} INFO - [2024-08-30T03:41:36.499+0000] {dagbag.py:587} INFO - Filling up the DagBag from /opt/airflow/dags/download_dag.py
[2024-08-30T03:41:36.654+0000] {logging_mixin.py:190} INFO - [2024-08-30T03:41:36.648+0000] {dagbag.py:386} ERROR - Failed to import: /opt/airflow/dags/download_dag.py
Traceback (most recent call last):
  File "/home/airflow/.local/lib/python3.12/site-packages/airflow/models/dagbag.py", line 382, in parse
    loader.exec_module(new_module)
  File "<frozen importlib._bootstrap_external>", line 995, in exec_module
  File "<frozen importlib._bootstrap>", line 488, in _call_with_frames_removed
  File "/opt/airflow/dags/download_dag.py", line 29, in <module>
    minio_client = Minio(
                   ^^^^^^
  File "/home/airflow/.local/lib/python3.12/site-packages/minio/api.py", line 153, in __init__
    ("https://" if secure else "http://") + endpoint,
    ~~~~~~~~~~~~~~~~~~~~~~~~~~~~~~~~~~~~~~^~~~~~~~~~
TypeError: can only concatenate str (not "NoneType") to str
[2024-08-30T03:41:36.656+0000] {processor.py:927} WARNING - No viable dags retrieved from /opt/airflow/dags/download_dag.py
[2024-08-30T03:41:36.670+0000] {processor.py:208} INFO - Processing /opt/airflow/dags/download_dag.py took 0.178 seconds
[2024-08-30T03:42:06.945+0000] {processor.py:186} INFO - Started process (PID=660) to work on /opt/airflow/dags/download_dag.py
[2024-08-30T03:42:06.947+0000] {processor.py:914} INFO - Processing file /opt/airflow/dags/download_dag.py for tasks to queue
[2024-08-30T03:42:06.949+0000] {logging_mixin.py:190} INFO - [2024-08-30T03:42:06.949+0000] {dagbag.py:587} INFO - Filling up the DagBag from /opt/airflow/dags/download_dag.py
[2024-08-30T03:42:07.088+0000] {logging_mixin.py:190} INFO - [2024-08-30T03:42:07.083+0000] {dagbag.py:386} ERROR - Failed to import: /opt/airflow/dags/download_dag.py
Traceback (most recent call last):
  File "/home/airflow/.local/lib/python3.12/site-packages/airflow/models/dagbag.py", line 382, in parse
    loader.exec_module(new_module)
  File "<frozen importlib._bootstrap_external>", line 995, in exec_module
  File "<frozen importlib._bootstrap>", line 488, in _call_with_frames_removed
  File "/opt/airflow/dags/download_dag.py", line 29, in <module>
    minio_client = Minio(
                   ^^^^^^
  File "/home/airflow/.local/lib/python3.12/site-packages/minio/api.py", line 153, in __init__
    ("https://" if secure else "http://") + endpoint,
    ~~~~~~~~~~~~~~~~~~~~~~~~~~~~~~~~~~~~~~^~~~~~~~~~
TypeError: can only concatenate str (not "NoneType") to str
[2024-08-30T03:42:07.089+0000] {processor.py:927} WARNING - No viable dags retrieved from /opt/airflow/dags/download_dag.py
[2024-08-30T03:42:07.103+0000] {processor.py:208} INFO - Processing /opt/airflow/dags/download_dag.py took 0.163 seconds
[2024-08-30T03:42:37.015+0000] {processor.py:186} INFO - Started process (PID=722) to work on /opt/airflow/dags/download_dag.py
[2024-08-30T03:42:37.016+0000] {processor.py:914} INFO - Processing file /opt/airflow/dags/download_dag.py for tasks to queue
[2024-08-30T03:42:37.018+0000] {logging_mixin.py:190} INFO - [2024-08-30T03:42:37.018+0000] {dagbag.py:587} INFO - Filling up the DagBag from /opt/airflow/dags/download_dag.py
[2024-08-30T03:42:37.184+0000] {logging_mixin.py:190} INFO - None
[2024-08-30T03:42:37.188+0000] {logging_mixin.py:190} INFO - [2024-08-30T03:42:37.185+0000] {dagbag.py:386} ERROR - Failed to import: /opt/airflow/dags/download_dag.py
Traceback (most recent call last):
  File "/home/airflow/.local/lib/python3.12/site-packages/airflow/models/dagbag.py", line 382, in parse
    loader.exec_module(new_module)
  File "<frozen importlib._bootstrap_external>", line 995, in exec_module
  File "<frozen importlib._bootstrap>", line 488, in _call_with_frames_removed
  File "/opt/airflow/dags/download_dag.py", line 29, in <module>
    minio_client = Minio(
                   ^^^^^^
  File "/home/airflow/.local/lib/python3.12/site-packages/minio/api.py", line 153, in __init__
    ("https://" if secure else "http://") + endpoint,
    ~~~~~~~~~~~~~~~~~~~~~~~~~~~~~~~~~~~~~~^~~~~~~~~~
TypeError: can only concatenate str (not "NoneType") to str
[2024-08-30T03:42:37.190+0000] {processor.py:927} WARNING - No viable dags retrieved from /opt/airflow/dags/download_dag.py
[2024-08-30T03:42:37.207+0000] {processor.py:208} INFO - Processing /opt/airflow/dags/download_dag.py took 0.196 seconds
[2024-08-30T03:42:55.822+0000] {processor.py:186} INFO - Started process (PID=755) to work on /opt/airflow/dags/download_dag.py
[2024-08-30T03:42:55.823+0000] {processor.py:914} INFO - Processing file /opt/airflow/dags/download_dag.py for tasks to queue
[2024-08-30T03:42:55.825+0000] {logging_mixin.py:190} INFO - [2024-08-30T03:42:55.824+0000] {dagbag.py:587} INFO - Filling up the DagBag from /opt/airflow/dags/download_dag.py
[2024-08-30T03:42:56.005+0000] {logging_mixin.py:190} INFO - [2024-08-30T03:42:55.997+0000] {dagbag.py:386} ERROR - Failed to import: /opt/airflow/dags/download_dag.py
Traceback (most recent call last):
  File "/home/airflow/.local/lib/python3.12/site-packages/airflow/models/dagbag.py", line 382, in parse
    loader.exec_module(new_module)
  File "<frozen importlib._bootstrap_external>", line 995, in exec_module
  File "<frozen importlib._bootstrap>", line 488, in _call_with_frames_removed
  File "/opt/airflow/dags/download_dag.py", line 29, in <module>
    minio_client = Minio(
                   ^^^^^^
  File "/home/airflow/.local/lib/python3.12/site-packages/minio/api.py", line 153, in __init__
    ("https://" if secure else "http://") + endpoint,
    ~~~~~~~~~~~~~~~~~~~~~~~~~~~~~~~~~~~~~~^~~~~~~~~~
TypeError: can only concatenate str (not "NoneType") to str
[2024-08-30T03:42:56.008+0000] {processor.py:927} WARNING - No viable dags retrieved from /opt/airflow/dags/download_dag.py
[2024-08-30T03:42:56.024+0000] {processor.py:208} INFO - Processing /opt/airflow/dags/download_dag.py took 0.206 seconds
[2024-08-30T03:43:26.439+0000] {processor.py:186} INFO - Started process (PID=818) to work on /opt/airflow/dags/download_dag.py
[2024-08-30T03:43:26.441+0000] {processor.py:914} INFO - Processing file /opt/airflow/dags/download_dag.py for tasks to queue
[2024-08-30T03:43:26.443+0000] {logging_mixin.py:190} INFO - [2024-08-30T03:43:26.442+0000] {dagbag.py:587} INFO - Filling up the DagBag from /opt/airflow/dags/download_dag.py
[2024-08-30T03:43:26.613+0000] {logging_mixin.py:190} INFO - [2024-08-30T03:43:26.605+0000] {dagbag.py:386} ERROR - Failed to import: /opt/airflow/dags/download_dag.py
Traceback (most recent call last):
  File "/home/airflow/.local/lib/python3.12/site-packages/airflow/models/dagbag.py", line 382, in parse
    loader.exec_module(new_module)
  File "<frozen importlib._bootstrap_external>", line 995, in exec_module
  File "<frozen importlib._bootstrap>", line 488, in _call_with_frames_removed
  File "/opt/airflow/dags/download_dag.py", line 29, in <module>
    minio_client = Minio(
                   ^^^^^^
  File "/home/airflow/.local/lib/python3.12/site-packages/minio/api.py", line 153, in __init__
    ("https://" if secure else "http://") + endpoint,
    ~~~~~~~~~~~~~~~~~~~~~~~~~~~~~~~~~~~~~~^~~~~~~~~~
TypeError: can only concatenate str (not "NoneType") to str
[2024-08-30T03:43:26.616+0000] {processor.py:927} WARNING - No viable dags retrieved from /opt/airflow/dags/download_dag.py
[2024-08-30T03:43:26.633+0000] {processor.py:208} INFO - Processing /opt/airflow/dags/download_dag.py took 0.199 seconds
[2024-08-30T03:43:33.538+0000] {processor.py:186} INFO - Started process (PID=825) to work on /opt/airflow/dags/download_dag.py
[2024-08-30T03:43:33.538+0000] {processor.py:914} INFO - Processing file /opt/airflow/dags/download_dag.py for tasks to queue
[2024-08-30T03:43:33.540+0000] {logging_mixin.py:190} INFO - [2024-08-30T03:43:33.540+0000] {dagbag.py:587} INFO - Filling up the DagBag from /opt/airflow/dags/download_dag.py
[2024-08-30T03:43:33.723+0000] {logging_mixin.py:190} INFO - [2024-08-30T03:43:33.717+0000] {dagbag.py:386} ERROR - Failed to import: /opt/airflow/dags/download_dag.py
Traceback (most recent call last):
  File "/home/airflow/.local/lib/python3.12/site-packages/airflow/models/dagbag.py", line 382, in parse
    loader.exec_module(new_module)
  File "<frozen importlib._bootstrap_external>", line 995, in exec_module
  File "<frozen importlib._bootstrap>", line 488, in _call_with_frames_removed
  File "/opt/airflow/dags/download_dag.py", line 29, in <module>
    minio_client = Minio(
                   ^^^^^^
  File "/home/airflow/.local/lib/python3.12/site-packages/minio/api.py", line 153, in __init__
    ("https://" if secure else "http://") + endpoint,
    ~~~~~~~~~~~~~~~~~~~~~~~~~~~~~~~~~~~~~~^~~~~~~~~~
TypeError: can only concatenate str (not "NoneType") to str
[2024-08-30T03:43:33.724+0000] {processor.py:927} WARNING - No viable dags retrieved from /opt/airflow/dags/download_dag.py
[2024-08-30T03:43:33.750+0000] {processor.py:208} INFO - Processing /opt/airflow/dags/download_dag.py took 0.217 seconds
[2024-08-30T03:44:04.729+0000] {processor.py:186} INFO - Started process (PID=888) to work on /opt/airflow/dags/download_dag.py
[2024-08-30T03:44:04.730+0000] {processor.py:914} INFO - Processing file /opt/airflow/dags/download_dag.py for tasks to queue
[2024-08-30T03:44:04.732+0000] {logging_mixin.py:190} INFO - [2024-08-30T03:44:04.732+0000] {dagbag.py:587} INFO - Filling up the DagBag from /opt/airflow/dags/download_dag.py
[2024-08-30T03:44:04.876+0000] {logging_mixin.py:190} INFO - [2024-08-30T03:44:04.872+0000] {dagbag.py:386} ERROR - Failed to import: /opt/airflow/dags/download_dag.py
Traceback (most recent call last):
  File "/home/airflow/.local/lib/python3.12/site-packages/airflow/models/dagbag.py", line 382, in parse
    loader.exec_module(new_module)
  File "<frozen importlib._bootstrap_external>", line 995, in exec_module
  File "<frozen importlib._bootstrap>", line 488, in _call_with_frames_removed
  File "/opt/airflow/dags/download_dag.py", line 29, in <module>
    minio_client = Minio(
                   ^^^^^^
  File "/home/airflow/.local/lib/python3.12/site-packages/minio/api.py", line 153, in __init__
    ("https://" if secure else "http://") + endpoint,
    ~~~~~~~~~~~~~~~~~~~~~~~~~~~~~~~~~~~~~~^~~~~~~~~~
TypeError: can only concatenate str (not "NoneType") to str
[2024-08-30T03:44:04.877+0000] {processor.py:927} WARNING - No viable dags retrieved from /opt/airflow/dags/download_dag.py
[2024-08-30T03:44:04.900+0000] {processor.py:208} INFO - Processing /opt/airflow/dags/download_dag.py took 0.175 seconds
[2024-08-30T03:44:35.442+0000] {processor.py:186} INFO - Started process (PID=951) to work on /opt/airflow/dags/download_dag.py
[2024-08-30T03:44:35.443+0000] {processor.py:914} INFO - Processing file /opt/airflow/dags/download_dag.py for tasks to queue
[2024-08-30T03:44:35.445+0000] {logging_mixin.py:190} INFO - [2024-08-30T03:44:35.445+0000] {dagbag.py:587} INFO - Filling up the DagBag from /opt/airflow/dags/download_dag.py
[2024-08-30T03:44:35.597+0000] {logging_mixin.py:190} INFO - [2024-08-30T03:44:35.593+0000] {dagbag.py:386} ERROR - Failed to import: /opt/airflow/dags/download_dag.py
Traceback (most recent call last):
  File "/home/airflow/.local/lib/python3.12/site-packages/airflow/models/dagbag.py", line 382, in parse
    loader.exec_module(new_module)
  File "<frozen importlib._bootstrap_external>", line 995, in exec_module
  File "<frozen importlib._bootstrap>", line 488, in _call_with_frames_removed
  File "/opt/airflow/dags/download_dag.py", line 29, in <module>
    minio_client = Minio(
                   ^^^^^^
  File "/home/airflow/.local/lib/python3.12/site-packages/minio/api.py", line 153, in __init__
    ("https://" if secure else "http://") + endpoint,
    ~~~~~~~~~~~~~~~~~~~~~~~~~~~~~~~~~~~~~~^~~~~~~~~~
TypeError: can only concatenate str (not "NoneType") to str
[2024-08-30T03:44:35.598+0000] {processor.py:927} WARNING - No viable dags retrieved from /opt/airflow/dags/download_dag.py
[2024-08-30T03:44:35.613+0000] {processor.py:208} INFO - Processing /opt/airflow/dags/download_dag.py took 0.175 seconds
[2024-08-30T03:44:51.946+0000] {processor.py:186} INFO - Started process (PID=1008) to work on /opt/airflow/dags/download_dag.py
[2024-08-30T03:44:51.947+0000] {processor.py:914} INFO - Processing file /opt/airflow/dags/download_dag.py for tasks to queue
[2024-08-30T03:44:51.949+0000] {logging_mixin.py:190} INFO - [2024-08-30T03:44:51.948+0000] {dagbag.py:587} INFO - Filling up the DagBag from /opt/airflow/dags/download_dag.py
[2024-08-30T03:44:52.151+0000] {logging_mixin.py:190} INFO - [2024-08-30T03:44:52.146+0000] {dagbag.py:386} ERROR - Failed to import: /opt/airflow/dags/download_dag.py
Traceback (most recent call last):
  File "/home/airflow/.local/lib/python3.12/site-packages/airflow/models/dagbag.py", line 382, in parse
    loader.exec_module(new_module)
  File "<frozen importlib._bootstrap_external>", line 995, in exec_module
  File "<frozen importlib._bootstrap>", line 488, in _call_with_frames_removed
  File "/opt/airflow/dags/download_dag.py", line 32, in <module>
    minio_client = Minio(
                   ^^^^^^
  File "/home/airflow/.local/lib/python3.12/site-packages/minio/api.py", line 153, in __init__
    ("https://" if secure else "http://") + endpoint,
    ~~~~~~~~~~~~~~~~~~~~~~~~~~~~~~~~~~~~~~^~~~~~~~~~
TypeError: can only concatenate str (not "NoneType") to str
[2024-08-30T03:44:52.154+0000] {processor.py:927} WARNING - No viable dags retrieved from /opt/airflow/dags/download_dag.py
[2024-08-30T03:44:52.171+0000] {processor.py:208} INFO - Processing /opt/airflow/dags/download_dag.py took 0.229 seconds
[2024-08-30T03:45:59.483+0000] {processor.py:186} INFO - Started process (PID=61) to work on /opt/airflow/dags/download_dag.py
[2024-08-30T03:45:59.484+0000] {processor.py:914} INFO - Processing file /opt/airflow/dags/download_dag.py for tasks to queue
[2024-08-30T03:45:59.486+0000] {logging_mixin.py:190} INFO - [2024-08-30T03:45:59.486+0000] {dagbag.py:587} INFO - Filling up the DagBag from /opt/airflow/dags/download_dag.py
[2024-08-30T03:45:59.839+0000] {processor.py:925} INFO - DAG(s) 'download_to_minio_dag' retrieved from /opt/airflow/dags/download_dag.py
[2024-08-30T03:45:59.982+0000] {logging_mixin.py:190} INFO - [2024-08-30T03:45:59.981+0000] {override.py:1858} INFO - Created Permission View: can read on DAG:download_to_minio_dag
[2024-08-30T03:45:59.992+0000] {logging_mixin.py:190} INFO - [2024-08-30T03:45:59.992+0000] {override.py:1858} INFO - Created Permission View: can edit on DAG:download_to_minio_dag
[2024-08-30T03:46:00.000+0000] {logging_mixin.py:190} INFO - [2024-08-30T03:46:00.000+0000] {override.py:1858} INFO - Created Permission View: can delete on DAG:download_to_minio_dag
[2024-08-30T03:46:00.001+0000] {logging_mixin.py:190} INFO - [2024-08-30T03:46:00.001+0000] {dag.py:3211} INFO - Sync 1 DAGs
[2024-08-30T03:46:00.012+0000] {logging_mixin.py:190} INFO - [2024-08-30T03:46:00.012+0000] {dag.py:3234} INFO - Creating ORM DAG for download_to_minio_dag
[2024-08-30T03:46:00.023+0000] {logging_mixin.py:190} INFO - [2024-08-30T03:46:00.023+0000] {dag.py:4138} INFO - Setting next_dagrun for download_to_minio_dag to 2024-08-29 00:00:00+00:00, run_after=2024-08-30 00:00:00+00:00
[2024-08-30T03:46:00.065+0000] {processor.py:208} INFO - Processing /opt/airflow/dags/download_dag.py took 0.586 seconds
[2024-08-30T03:46:12.794+0000] {processor.py:186} INFO - Started process (PID=55) to work on /opt/airflow/dags/download_dag.py
[2024-08-30T03:46:12.795+0000] {processor.py:914} INFO - Processing file /opt/airflow/dags/download_dag.py for tasks to queue
[2024-08-30T03:46:12.797+0000] {logging_mixin.py:190} INFO - [2024-08-30T03:46:12.797+0000] {dagbag.py:587} INFO - Filling up the DagBag from /opt/airflow/dags/download_dag.py
[2024-08-30T03:46:12.948+0000] {processor.py:925} INFO - DAG(s) 'download_to_minio_dag' retrieved from /opt/airflow/dags/download_dag.py
[2024-08-30T03:46:12.956+0000] {logging_mixin.py:190} INFO - [2024-08-30T03:46:12.956+0000] {dag.py:3211} INFO - Sync 1 DAGs
[2024-08-30T03:46:12.972+0000] {logging_mixin.py:190} INFO - [2024-08-30T03:46:12.972+0000] {dag.py:4138} INFO - Setting next_dagrun for download_to_minio_dag to 2024-08-29 00:00:00+00:00, run_after=2024-08-30 00:00:00+00:00
[2024-08-30T03:46:12.988+0000] {processor.py:208} INFO - Processing /opt/airflow/dags/download_dag.py took 0.198 seconds
[2024-08-30T03:46:43.540+0000] {processor.py:186} INFO - Started process (PID=118) to work on /opt/airflow/dags/download_dag.py
[2024-08-30T03:46:43.544+0000] {processor.py:914} INFO - Processing file /opt/airflow/dags/download_dag.py for tasks to queue
[2024-08-30T03:46:43.547+0000] {logging_mixin.py:190} INFO - [2024-08-30T03:46:43.546+0000] {dagbag.py:587} INFO - Filling up the DagBag from /opt/airflow/dags/download_dag.py
[2024-08-30T03:46:43.701+0000] {processor.py:925} INFO - DAG(s) 'download_to_minio_dag' retrieved from /opt/airflow/dags/download_dag.py
[2024-08-30T03:46:43.716+0000] {logging_mixin.py:190} INFO - [2024-08-30T03:46:43.716+0000] {dag.py:3211} INFO - Sync 1 DAGs
[2024-08-30T03:46:43.742+0000] {logging_mixin.py:190} INFO - [2024-08-30T03:46:43.742+0000] {dag.py:4138} INFO - Setting next_dagrun for download_to_minio_dag to 2024-08-29 00:00:00+00:00, run_after=2024-08-30 00:00:00+00:00
[2024-08-30T03:46:43.758+0000] {processor.py:208} INFO - Processing /opt/airflow/dags/download_dag.py took 0.224 seconds
[2024-08-30T03:47:13.939+0000] {processor.py:186} INFO - Started process (PID=181) to work on /opt/airflow/dags/download_dag.py
[2024-08-30T03:47:13.940+0000] {processor.py:914} INFO - Processing file /opt/airflow/dags/download_dag.py for tasks to queue
[2024-08-30T03:47:13.943+0000] {logging_mixin.py:190} INFO - [2024-08-30T03:47:13.942+0000] {dagbag.py:587} INFO - Filling up the DagBag from /opt/airflow/dags/download_dag.py
[2024-08-30T03:47:14.095+0000] {processor.py:925} INFO - DAG(s) 'download_to_minio_dag' retrieved from /opt/airflow/dags/download_dag.py
[2024-08-30T03:47:14.108+0000] {logging_mixin.py:190} INFO - [2024-08-30T03:47:14.108+0000] {dag.py:3211} INFO - Sync 1 DAGs
[2024-08-30T03:47:14.123+0000] {logging_mixin.py:190} INFO - [2024-08-30T03:47:14.123+0000] {dag.py:4138} INFO - Setting next_dagrun for download_to_minio_dag to 2024-08-29 00:00:00+00:00, run_after=2024-08-30 00:00:00+00:00
[2024-08-30T03:47:14.139+0000] {processor.py:208} INFO - Processing /opt/airflow/dags/download_dag.py took 0.205 seconds
[2024-08-30T03:47:45.004+0000] {processor.py:186} INFO - Started process (PID=244) to work on /opt/airflow/dags/download_dag.py
[2024-08-30T03:47:45.005+0000] {processor.py:914} INFO - Processing file /opt/airflow/dags/download_dag.py for tasks to queue
[2024-08-30T03:47:45.007+0000] {logging_mixin.py:190} INFO - [2024-08-30T03:47:45.006+0000] {dagbag.py:587} INFO - Filling up the DagBag from /opt/airflow/dags/download_dag.py
[2024-08-30T03:47:45.177+0000] {processor.py:925} INFO - DAG(s) 'download_to_minio_dag' retrieved from /opt/airflow/dags/download_dag.py
[2024-08-30T03:47:45.191+0000] {logging_mixin.py:190} INFO - [2024-08-30T03:47:45.191+0000] {dag.py:3211} INFO - Sync 1 DAGs
[2024-08-30T03:47:45.206+0000] {logging_mixin.py:190} INFO - [2024-08-30T03:47:45.206+0000] {dag.py:4138} INFO - Setting next_dagrun for download_to_minio_dag to 2024-08-29 00:00:00+00:00, run_after=2024-08-30 00:00:00+00:00
[2024-08-30T03:47:45.220+0000] {processor.py:208} INFO - Processing /opt/airflow/dags/download_dag.py took 0.220 seconds
[2024-08-30T03:48:15.324+0000] {processor.py:186} INFO - Started process (PID=307) to work on /opt/airflow/dags/download_dag.py
[2024-08-30T03:48:15.325+0000] {processor.py:914} INFO - Processing file /opt/airflow/dags/download_dag.py for tasks to queue
[2024-08-30T03:48:15.327+0000] {logging_mixin.py:190} INFO - [2024-08-30T03:48:15.327+0000] {dagbag.py:587} INFO - Filling up the DagBag from /opt/airflow/dags/download_dag.py
[2024-08-30T03:48:15.477+0000] {processor.py:925} INFO - DAG(s) 'download_to_minio_dag' retrieved from /opt/airflow/dags/download_dag.py
[2024-08-30T03:48:15.490+0000] {logging_mixin.py:190} INFO - [2024-08-30T03:48:15.490+0000] {dag.py:3211} INFO - Sync 1 DAGs
[2024-08-30T03:48:15.507+0000] {logging_mixin.py:190} INFO - [2024-08-30T03:48:15.507+0000] {dag.py:4138} INFO - Setting next_dagrun for download_to_minio_dag to 2024-08-29 00:00:00+00:00, run_after=2024-08-30 00:00:00+00:00
[2024-08-30T03:48:15.524+0000] {processor.py:208} INFO - Processing /opt/airflow/dags/download_dag.py took 0.204 seconds
[2024-08-30T03:48:45.928+0000] {processor.py:186} INFO - Started process (PID=374) to work on /opt/airflow/dags/download_dag.py
[2024-08-30T03:48:45.929+0000] {processor.py:914} INFO - Processing file /opt/airflow/dags/download_dag.py for tasks to queue
[2024-08-30T03:48:45.931+0000] {logging_mixin.py:190} INFO - [2024-08-30T03:48:45.931+0000] {dagbag.py:587} INFO - Filling up the DagBag from /opt/airflow/dags/download_dag.py
[2024-08-30T03:48:46.094+0000] {processor.py:925} INFO - DAG(s) 'download_to_minio_dag' retrieved from /opt/airflow/dags/download_dag.py
[2024-08-30T03:48:46.109+0000] {logging_mixin.py:190} INFO - [2024-08-30T03:48:46.109+0000] {dag.py:3211} INFO - Sync 1 DAGs
[2024-08-30T03:48:46.127+0000] {logging_mixin.py:190} INFO - [2024-08-30T03:48:46.127+0000] {dag.py:4138} INFO - Setting next_dagrun for download_to_minio_dag to 2024-08-30 00:00:00+00:00, run_after=2024-08-31 00:00:00+00:00
[2024-08-30T03:48:46.146+0000] {processor.py:208} INFO - Processing /opt/airflow/dags/download_dag.py took 0.223 seconds
[2024-08-30T03:49:16.882+0000] {processor.py:186} INFO - Started process (PID=437) to work on /opt/airflow/dags/download_dag.py
[2024-08-30T03:49:16.884+0000] {processor.py:914} INFO - Processing file /opt/airflow/dags/download_dag.py for tasks to queue
[2024-08-30T03:49:16.886+0000] {logging_mixin.py:190} INFO - [2024-08-30T03:49:16.886+0000] {dagbag.py:587} INFO - Filling up the DagBag from /opt/airflow/dags/download_dag.py
[2024-08-30T03:49:17.046+0000] {processor.py:925} INFO - DAG(s) 'download_to_minio_dag' retrieved from /opt/airflow/dags/download_dag.py
[2024-08-30T03:49:17.060+0000] {logging_mixin.py:190} INFO - [2024-08-30T03:49:17.059+0000] {dag.py:3211} INFO - Sync 1 DAGs
[2024-08-30T03:49:17.074+0000] {logging_mixin.py:190} INFO - [2024-08-30T03:49:17.074+0000] {dag.py:4138} INFO - Setting next_dagrun for download_to_minio_dag to 2024-08-30 00:00:00+00:00, run_after=2024-08-31 00:00:00+00:00
[2024-08-30T03:49:17.090+0000] {processor.py:208} INFO - Processing /opt/airflow/dags/download_dag.py took 0.212 seconds
[2024-08-30T03:49:40.435+0000] {processor.py:186} INFO - Started process (PID=500) to work on /opt/airflow/dags/download_dag.py
[2024-08-30T03:49:40.436+0000] {processor.py:914} INFO - Processing file /opt/airflow/dags/download_dag.py for tasks to queue
[2024-08-30T03:49:40.438+0000] {logging_mixin.py:190} INFO - [2024-08-30T03:49:40.437+0000] {dagbag.py:587} INFO - Filling up the DagBag from /opt/airflow/dags/download_dag.py
[2024-08-30T03:49:40.625+0000] {processor.py:925} INFO - DAG(s) 'download_to_minio_dag' retrieved from /opt/airflow/dags/download_dag.py
[2024-08-30T03:49:40.637+0000] {logging_mixin.py:190} INFO - [2024-08-30T03:49:40.637+0000] {dag.py:3211} INFO - Sync 1 DAGs
[2024-08-30T03:49:40.653+0000] {logging_mixin.py:190} INFO - [2024-08-30T03:49:40.653+0000] {dag.py:4138} INFO - Setting next_dagrun for download_to_minio_dag to 2024-08-30 00:00:00+00:00, run_after=2024-08-31 00:00:00+00:00
[2024-08-30T03:49:40.673+0000] {processor.py:208} INFO - Processing /opt/airflow/dags/download_dag.py took 0.242 seconds
[2024-08-30T03:50:11.603+0000] {processor.py:186} INFO - Started process (PID=563) to work on /opt/airflow/dags/download_dag.py
[2024-08-30T03:50:11.604+0000] {processor.py:914} INFO - Processing file /opt/airflow/dags/download_dag.py for tasks to queue
[2024-08-30T03:50:11.607+0000] {logging_mixin.py:190} INFO - [2024-08-30T03:50:11.606+0000] {dagbag.py:587} INFO - Filling up the DagBag from /opt/airflow/dags/download_dag.py
[2024-08-30T03:50:11.788+0000] {processor.py:925} INFO - DAG(s) 'download_to_minio_dag' retrieved from /opt/airflow/dags/download_dag.py
[2024-08-30T03:50:11.805+0000] {logging_mixin.py:190} INFO - [2024-08-30T03:50:11.805+0000] {dag.py:3211} INFO - Sync 1 DAGs
[2024-08-30T03:50:11.823+0000] {logging_mixin.py:190} INFO - [2024-08-30T03:50:11.823+0000] {dag.py:4138} INFO - Setting next_dagrun for download_to_minio_dag to 2024-08-30 00:00:00+00:00, run_after=2024-08-31 00:00:00+00:00
[2024-08-30T03:50:11.851+0000] {processor.py:208} INFO - Processing /opt/airflow/dags/download_dag.py took 0.252 seconds
[2024-08-30T03:50:42.398+0000] {processor.py:186} INFO - Started process (PID=626) to work on /opt/airflow/dags/download_dag.py
[2024-08-30T03:50:42.399+0000] {processor.py:914} INFO - Processing file /opt/airflow/dags/download_dag.py for tasks to queue
[2024-08-30T03:50:42.401+0000] {logging_mixin.py:190} INFO - [2024-08-30T03:50:42.401+0000] {dagbag.py:587} INFO - Filling up the DagBag from /opt/airflow/dags/download_dag.py
[2024-08-30T03:50:42.544+0000] {processor.py:925} INFO - DAG(s) 'download_to_minio_dag' retrieved from /opt/airflow/dags/download_dag.py
[2024-08-30T03:50:42.563+0000] {logging_mixin.py:190} INFO - [2024-08-30T03:50:42.563+0000] {dag.py:3211} INFO - Sync 1 DAGs
[2024-08-30T03:50:42.584+0000] {logging_mixin.py:190} INFO - [2024-08-30T03:50:42.584+0000] {dag.py:4138} INFO - Setting next_dagrun for download_to_minio_dag to 2024-08-30 00:00:00+00:00, run_after=2024-08-31 00:00:00+00:00
[2024-08-30T03:50:42.602+0000] {processor.py:208} INFO - Processing /opt/airflow/dags/download_dag.py took 0.208 seconds
[2024-08-30T03:51:13.393+0000] {processor.py:186} INFO - Started process (PID=689) to work on /opt/airflow/dags/download_dag.py
[2024-08-30T03:51:13.394+0000] {processor.py:914} INFO - Processing file /opt/airflow/dags/download_dag.py for tasks to queue
[2024-08-30T03:51:13.396+0000] {logging_mixin.py:190} INFO - [2024-08-30T03:51:13.396+0000] {dagbag.py:587} INFO - Filling up the DagBag from /opt/airflow/dags/download_dag.py
[2024-08-30T03:51:13.555+0000] {processor.py:925} INFO - DAG(s) 'download_to_minio_dag' retrieved from /opt/airflow/dags/download_dag.py
[2024-08-30T03:51:13.571+0000] {logging_mixin.py:190} INFO - [2024-08-30T03:51:13.571+0000] {dag.py:3211} INFO - Sync 1 DAGs
[2024-08-30T03:51:13.588+0000] {logging_mixin.py:190} INFO - [2024-08-30T03:51:13.588+0000] {dag.py:4138} INFO - Setting next_dagrun for download_to_minio_dag to 2024-08-30 00:00:00+00:00, run_after=2024-08-31 00:00:00+00:00
[2024-08-30T03:51:13.606+0000] {processor.py:208} INFO - Processing /opt/airflow/dags/download_dag.py took 0.217 seconds
[2024-08-30T03:51:44.226+0000] {processor.py:186} INFO - Started process (PID=752) to work on /opt/airflow/dags/download_dag.py
[2024-08-30T03:51:44.227+0000] {processor.py:914} INFO - Processing file /opt/airflow/dags/download_dag.py for tasks to queue
[2024-08-30T03:51:44.230+0000] {logging_mixin.py:190} INFO - [2024-08-30T03:51:44.229+0000] {dagbag.py:587} INFO - Filling up the DagBag from /opt/airflow/dags/download_dag.py
[2024-08-30T03:51:44.390+0000] {processor.py:925} INFO - DAG(s) 'download_to_minio_dag' retrieved from /opt/airflow/dags/download_dag.py
[2024-08-30T03:51:44.405+0000] {logging_mixin.py:190} INFO - [2024-08-30T03:51:44.405+0000] {dag.py:3211} INFO - Sync 1 DAGs
[2024-08-30T03:51:44.423+0000] {logging_mixin.py:190} INFO - [2024-08-30T03:51:44.423+0000] {dag.py:4138} INFO - Setting next_dagrun for download_to_minio_dag to 2024-08-30 00:00:00+00:00, run_after=2024-08-31 00:00:00+00:00
[2024-08-30T03:51:44.440+0000] {processor.py:208} INFO - Processing /opt/airflow/dags/download_dag.py took 0.219 seconds
[2024-08-30T03:52:00.658+0000] {processor.py:186} INFO - Started process (PID=815) to work on /opt/airflow/dags/download_dag.py
[2024-08-30T03:52:00.660+0000] {processor.py:914} INFO - Processing file /opt/airflow/dags/download_dag.py for tasks to queue
[2024-08-30T03:52:00.665+0000] {logging_mixin.py:190} INFO - [2024-08-30T03:52:00.664+0000] {dagbag.py:587} INFO - Filling up the DagBag from /opt/airflow/dags/download_dag.py
[2024-08-30T03:52:00.853+0000] {logging_mixin.py:190} INFO - [2024-08-30T03:52:00.853+0000] {__init__.py:49} INFO - file_cache is only supported with oauth2client<4.0.0
[2024-08-30T03:52:03.503+0000] {logging_mixin.py:190} INFO - Downloading Nhóm 4 - Lê Duy Khang - 2152108.JPG: 100%.
[2024-08-30T03:52:03.505+0000] {logging_mixin.py:190} INFO - [2024-08-30T03:52:03.505+0000] {connectionpool.py:870} WARNING - Retrying (Retry(total=4, connect=None, read=None, redirect=None, status=None)) after connection broken by 'NewConnectionError('<urllib3.connection.HTTPConnection object at 0x7f0fd94843b0>: Failed to establish a new connection: [Errno 111] Connection refused')': /drive-fetch?location=
[2024-08-30T03:52:03.907+0000] {logging_mixin.py:190} INFO - [2024-08-30T03:52:03.906+0000] {connectionpool.py:870} WARNING - Retrying (Retry(total=3, connect=None, read=None, redirect=None, status=None)) after connection broken by 'NewConnectionError('<urllib3.connection.HTTPConnection object at 0x7f0fd94861b0>: Failed to establish a new connection: [Errno 111] Connection refused')': /drive-fetch?location=
[2024-08-30T03:52:04.709+0000] {logging_mixin.py:190} INFO - [2024-08-30T03:52:04.709+0000] {connectionpool.py:870} WARNING - Retrying (Retry(total=2, connect=None, read=None, redirect=None, status=None)) after connection broken by 'NewConnectionError('<urllib3.connection.HTTPConnection object at 0x7f0fd9486a50>: Failed to establish a new connection: [Errno 111] Connection refused')': /drive-fetch?location=
[2024-08-30T03:52:06.311+0000] {logging_mixin.py:190} INFO - [2024-08-30T03:52:06.311+0000] {connectionpool.py:870} WARNING - Retrying (Retry(total=1, connect=None, read=None, redirect=None, status=None)) after connection broken by 'NewConnectionError('<urllib3.connection.HTTPConnection object at 0x7f0fd9486ff0>: Failed to establish a new connection: [Errno 111] Connection refused')': /drive-fetch?location=
[2024-08-30T03:52:09.514+0000] {logging_mixin.py:190} INFO - [2024-08-30T03:52:09.513+0000] {connectionpool.py:870} WARNING - Retrying (Retry(total=0, connect=None, read=None, redirect=None, status=None)) after connection broken by 'NewConnectionError('<urllib3.connection.HTTPConnection object at 0x7f0fd94878f0>: Failed to establish a new connection: [Errno 111] Connection refused')': /drive-fetch?location=
[2024-08-30T03:52:09.524+0000] {logging_mixin.py:190} INFO - [2024-08-30T03:52:09.515+0000] {dagbag.py:386} ERROR - Failed to import: /opt/airflow/dags/download_dag.py
Traceback (most recent call last):
  File "/home/airflow/.local/lib/python3.12/site-packages/urllib3/connection.py", line 196, in _new_conn
    sock = connection.create_connection(
           ^^^^^^^^^^^^^^^^^^^^^^^^^^^^^
  File "/home/airflow/.local/lib/python3.12/site-packages/urllib3/util/connection.py", line 85, in create_connection
    raise err
  File "/home/airflow/.local/lib/python3.12/site-packages/urllib3/util/connection.py", line 73, in create_connection
    sock.connect(sa)
ConnectionRefusedError: [Errno 111] Connection refused

The above exception was the direct cause of the following exception:

Traceback (most recent call last):
  File "/home/airflow/.local/lib/python3.12/site-packages/urllib3/connectionpool.py", line 789, in urlopen
    response = self._make_request(
               ^^^^^^^^^^^^^^^^^^^
  File "/home/airflow/.local/lib/python3.12/site-packages/urllib3/connectionpool.py", line 495, in _make_request
    conn.request(
  File "/home/airflow/.local/lib/python3.12/site-packages/urllib3/connection.py", line 398, in request
    self.endheaders()
  File "/usr/local/lib/python3.12/http/client.py", line 1331, in endheaders
    self._send_output(message_body, encode_chunked=encode_chunked)
  File "/usr/local/lib/python3.12/http/client.py", line 1091, in _send_output
    self.send(msg)
  File "/usr/local/lib/python3.12/http/client.py", line 1035, in send
    self.connect()
  File "/home/airflow/.local/lib/python3.12/site-packages/urllib3/connection.py", line 236, in connect
    self.sock = self._new_conn()
                ^^^^^^^^^^^^^^^^
  File "/home/airflow/.local/lib/python3.12/site-packages/urllib3/connection.py", line 211, in _new_conn
    raise NewConnectionError(
urllib3.exceptions.NewConnectionError: <urllib3.connection.HTTPConnection object at 0x7f0fd9487e00>: Failed to establish a new connection: [Errno 111] Connection refused

The above exception was the direct cause of the following exception:

Traceback (most recent call last):
  File "/home/airflow/.local/lib/python3.12/site-packages/airflow/models/dagbag.py", line 382, in parse
    loader.exec_module(new_module)
  File "<frozen importlib._bootstrap_external>", line 995, in exec_module
  File "<frozen importlib._bootstrap>", line 488, in _call_with_frames_removed
  File "/opt/airflow/dags/download_dag.py", line 111, in <module>
    python_callable=download_to_minio(authenticate_gdrive(), FOLDER_ID),
                    ^^^^^^^^^^^^^^^^^^^^^^^^^^^^^^^^^^^^^^^^^^^^^^^^^^^
  File "/opt/airflow/dags/download_dag.py", line 78, in download_to_minio
    minio_client.put_object(
  File "/home/airflow/.local/lib/python3.12/site-packages/minio/api.py", line 1922, in put_object
    raise exc
  File "/home/airflow/.local/lib/python3.12/site-packages/minio/api.py", line 1868, in put_object
    return self._put_object(
           ^^^^^^^^^^^^^^^^^
  File "/home/airflow/.local/lib/python3.12/site-packages/minio/api.py", line 1707, in _put_object
    response = self._execute(
               ^^^^^^^^^^^^^^
  File "/home/airflow/.local/lib/python3.12/site-packages/minio/api.py", line 437, in _execute
    region = self._get_region(bucket_name)
             ^^^^^^^^^^^^^^^^^^^^^^^^^^^^^
  File "/home/airflow/.local/lib/python3.12/site-packages/minio/api.py", line 494, in _get_region
    response = self._url_open(
               ^^^^^^^^^^^^^^^
  File "/home/airflow/.local/lib/python3.12/site-packages/minio/api.py", line 302, in _url_open
    response = self._http.urlopen(
               ^^^^^^^^^^^^^^^^^^^
  File "/home/airflow/.local/lib/python3.12/site-packages/urllib3/poolmanager.py", line 443, in urlopen
    response = conn.urlopen(method, u.request_uri, **kw)
               ^^^^^^^^^^^^^^^^^^^^^^^^^^^^^^^^^^^^^^^^^
  File "/home/airflow/.local/lib/python3.12/site-packages/urllib3/connectionpool.py", line 873, in urlopen
    return self.urlopen(
           ^^^^^^^^^^^^^
  File "/home/airflow/.local/lib/python3.12/site-packages/urllib3/connectionpool.py", line 873, in urlopen
    return self.urlopen(
           ^^^^^^^^^^^^^
  File "/home/airflow/.local/lib/python3.12/site-packages/urllib3/connectionpool.py", line 873, in urlopen
    return self.urlopen(
           ^^^^^^^^^^^^^
  [Previous line repeated 2 more times]
  File "/home/airflow/.local/lib/python3.12/site-packages/urllib3/connectionpool.py", line 843, in urlopen
    retries = retries.increment(
              ^^^^^^^^^^^^^^^^^^
  File "/home/airflow/.local/lib/python3.12/site-packages/urllib3/util/retry.py", line 519, in increment
    raise MaxRetryError(_pool, url, reason) from reason  # type: ignore[arg-type]
    ^^^^^^^^^^^^^^^^^^^^^^^^^^^^^^^^^^^^^^^^^^^^^^^^^^^
urllib3.exceptions.MaxRetryError: HTTPConnectionPool(host='localhost', port=9000): Max retries exceeded with url: /drive-fetch?location= (Caused by NewConnectionError('<urllib3.connection.HTTPConnection object at 0x7f0fd9487e00>: Failed to establish a new connection: [Errno 111] Connection refused'))
[2024-08-30T03:52:09.525+0000] {processor.py:927} WARNING - No viable dags retrieved from /opt/airflow/dags/download_dag.py
[2024-08-30T03:52:09.542+0000] {processor.py:208} INFO - Processing /opt/airflow/dags/download_dag.py took 8.890 seconds
[2024-08-30T03:52:40.420+0000] {processor.py:186} INFO - Started process (PID=878) to work on /opt/airflow/dags/download_dag.py
[2024-08-30T03:52:40.421+0000] {processor.py:914} INFO - Processing file /opt/airflow/dags/download_dag.py for tasks to queue
[2024-08-30T03:52:40.422+0000] {logging_mixin.py:190} INFO - [2024-08-30T03:52:40.422+0000] {dagbag.py:587} INFO - Filling up the DagBag from /opt/airflow/dags/download_dag.py
[2024-08-30T03:52:40.598+0000] {logging_mixin.py:190} INFO - [2024-08-30T03:52:40.597+0000] {__init__.py:49} INFO - file_cache is only supported with oauth2client<4.0.0
[2024-08-30T03:52:42.358+0000] {logging_mixin.py:190} INFO - Downloading Nhóm 4 - Lê Duy Khang - 2152108.JPG: 100%.
[2024-08-30T03:52:42.360+0000] {logging_mixin.py:190} INFO - [2024-08-30T03:52:42.360+0000] {connectionpool.py:870} WARNING - Retrying (Retry(total=4, connect=None, read=None, redirect=None, status=None)) after connection broken by 'NewConnectionError('<urllib3.connection.HTTPConnection object at 0x7f0fd9484380>: Failed to establish a new connection: [Errno 111] Connection refused')': /drive-fetch?location=
[2024-08-30T03:52:42.762+0000] {logging_mixin.py:190} INFO - [2024-08-30T03:52:42.762+0000] {connectionpool.py:870} WARNING - Retrying (Retry(total=3, connect=None, read=None, redirect=None, status=None)) after connection broken by 'NewConnectionError('<urllib3.connection.HTTPConnection object at 0x7f0fd94842f0>: Failed to establish a new connection: [Errno 111] Connection refused')': /drive-fetch?location=
[2024-08-30T03:52:43.565+0000] {logging_mixin.py:190} INFO - [2024-08-30T03:52:43.564+0000] {connectionpool.py:870} WARNING - Retrying (Retry(total=2, connect=None, read=None, redirect=None, status=None)) after connection broken by 'NewConnectionError('<urllib3.connection.HTTPConnection object at 0x7f0fd9486540>: Failed to establish a new connection: [Errno 111] Connection refused')': /drive-fetch?location=
[2024-08-30T03:52:45.171+0000] {logging_mixin.py:190} INFO - [2024-08-30T03:52:45.170+0000] {connectionpool.py:870} WARNING - Retrying (Retry(total=1, connect=None, read=None, redirect=None, status=None)) after connection broken by 'NewConnectionError('<urllib3.connection.HTTPConnection object at 0x7f0fd9486ae0>: Failed to establish a new connection: [Errno 111] Connection refused')': /drive-fetch?location=
[2024-08-30T03:52:48.374+0000] {logging_mixin.py:190} INFO - [2024-08-30T03:52:48.374+0000] {connectionpool.py:870} WARNING - Retrying (Retry(total=0, connect=None, read=None, redirect=None, status=None)) after connection broken by 'NewConnectionError('<urllib3.connection.HTTPConnection object at 0x7f0fd9486fc0>: Failed to establish a new connection: [Errno 111] Connection refused')': /drive-fetch?location=
[2024-08-30T03:52:48.382+0000] {logging_mixin.py:190} INFO - [2024-08-30T03:52:48.375+0000] {dagbag.py:386} ERROR - Failed to import: /opt/airflow/dags/download_dag.py
Traceback (most recent call last):
  File "/home/airflow/.local/lib/python3.12/site-packages/urllib3/connection.py", line 196, in _new_conn
    sock = connection.create_connection(
           ^^^^^^^^^^^^^^^^^^^^^^^^^^^^^
  File "/home/airflow/.local/lib/python3.12/site-packages/urllib3/util/connection.py", line 85, in create_connection
    raise err
  File "/home/airflow/.local/lib/python3.12/site-packages/urllib3/util/connection.py", line 73, in create_connection
    sock.connect(sa)
ConnectionRefusedError: [Errno 111] Connection refused

The above exception was the direct cause of the following exception:

Traceback (most recent call last):
  File "/home/airflow/.local/lib/python3.12/site-packages/urllib3/connectionpool.py", line 789, in urlopen
    response = self._make_request(
               ^^^^^^^^^^^^^^^^^^^
  File "/home/airflow/.local/lib/python3.12/site-packages/urllib3/connectionpool.py", line 495, in _make_request
    conn.request(
  File "/home/airflow/.local/lib/python3.12/site-packages/urllib3/connection.py", line 398, in request
    self.endheaders()
  File "/usr/local/lib/python3.12/http/client.py", line 1331, in endheaders
    self._send_output(message_body, encode_chunked=encode_chunked)
  File "/usr/local/lib/python3.12/http/client.py", line 1091, in _send_output
    self.send(msg)
  File "/usr/local/lib/python3.12/http/client.py", line 1035, in send
    self.connect()
  File "/home/airflow/.local/lib/python3.12/site-packages/urllib3/connection.py", line 236, in connect
    self.sock = self._new_conn()
                ^^^^^^^^^^^^^^^^
  File "/home/airflow/.local/lib/python3.12/site-packages/urllib3/connection.py", line 211, in _new_conn
    raise NewConnectionError(
urllib3.exceptions.NewConnectionError: <urllib3.connection.HTTPConnection object at 0x7f0fd94872c0>: Failed to establish a new connection: [Errno 111] Connection refused

The above exception was the direct cause of the following exception:

Traceback (most recent call last):
  File "/home/airflow/.local/lib/python3.12/site-packages/airflow/models/dagbag.py", line 382, in parse
    loader.exec_module(new_module)
  File "<frozen importlib._bootstrap_external>", line 995, in exec_module
  File "<frozen importlib._bootstrap>", line 488, in _call_with_frames_removed
  File "/opt/airflow/dags/download_dag.py", line 111, in <module>
    python_callable=download_to_minio(authenticate_gdrive(), FOLDER_ID),
                    ^^^^^^^^^^^^^^^^^^^^^^^^^^^^^^^^^^^^^^^^^^^^^^^^^^^
  File "/opt/airflow/dags/download_dag.py", line 78, in download_to_minio
    minio_client.put_object(
  File "/home/airflow/.local/lib/python3.12/site-packages/minio/api.py", line 1922, in put_object
    raise exc
  File "/home/airflow/.local/lib/python3.12/site-packages/minio/api.py", line 1868, in put_object
    return self._put_object(
           ^^^^^^^^^^^^^^^^^
  File "/home/airflow/.local/lib/python3.12/site-packages/minio/api.py", line 1707, in _put_object
    response = self._execute(
               ^^^^^^^^^^^^^^
  File "/home/airflow/.local/lib/python3.12/site-packages/minio/api.py", line 437, in _execute
    region = self._get_region(bucket_name)
             ^^^^^^^^^^^^^^^^^^^^^^^^^^^^^
  File "/home/airflow/.local/lib/python3.12/site-packages/minio/api.py", line 494, in _get_region
    response = self._url_open(
               ^^^^^^^^^^^^^^^
  File "/home/airflow/.local/lib/python3.12/site-packages/minio/api.py", line 302, in _url_open
    response = self._http.urlopen(
               ^^^^^^^^^^^^^^^^^^^
  File "/home/airflow/.local/lib/python3.12/site-packages/urllib3/poolmanager.py", line 443, in urlopen
    response = conn.urlopen(method, u.request_uri, **kw)
               ^^^^^^^^^^^^^^^^^^^^^^^^^^^^^^^^^^^^^^^^^
  File "/home/airflow/.local/lib/python3.12/site-packages/urllib3/connectionpool.py", line 873, in urlopen
    return self.urlopen(
           ^^^^^^^^^^^^^
  File "/home/airflow/.local/lib/python3.12/site-packages/urllib3/connectionpool.py", line 873, in urlopen
    return self.urlopen(
           ^^^^^^^^^^^^^
  File "/home/airflow/.local/lib/python3.12/site-packages/urllib3/connectionpool.py", line 873, in urlopen
    return self.urlopen(
           ^^^^^^^^^^^^^
  [Previous line repeated 2 more times]
  File "/home/airflow/.local/lib/python3.12/site-packages/urllib3/connectionpool.py", line 843, in urlopen
    retries = retries.increment(
              ^^^^^^^^^^^^^^^^^^
  File "/home/airflow/.local/lib/python3.12/site-packages/urllib3/util/retry.py", line 519, in increment
    raise MaxRetryError(_pool, url, reason) from reason  # type: ignore[arg-type]
    ^^^^^^^^^^^^^^^^^^^^^^^^^^^^^^^^^^^^^^^^^^^^^^^^^^^
urllib3.exceptions.MaxRetryError: HTTPConnectionPool(host='localhost', port=9000): Max retries exceeded with url: /drive-fetch?location= (Caused by NewConnectionError('<urllib3.connection.HTTPConnection object at 0x7f0fd94872c0>: Failed to establish a new connection: [Errno 111] Connection refused'))
[2024-08-30T03:52:48.383+0000] {processor.py:927} WARNING - No viable dags retrieved from /opt/airflow/dags/download_dag.py
[2024-08-30T03:52:48.412+0000] {processor.py:208} INFO - Processing /opt/airflow/dags/download_dag.py took 7.997 seconds
[2024-08-30T03:53:18.671+0000] {processor.py:186} INFO - Started process (PID=947) to work on /opt/airflow/dags/download_dag.py
[2024-08-30T03:53:18.671+0000] {processor.py:914} INFO - Processing file /opt/airflow/dags/download_dag.py for tasks to queue
[2024-08-30T03:53:18.673+0000] {logging_mixin.py:190} INFO - [2024-08-30T03:53:18.672+0000] {dagbag.py:587} INFO - Filling up the DagBag from /opt/airflow/dags/download_dag.py
[2024-08-30T03:53:18.848+0000] {logging_mixin.py:190} INFO - [2024-08-30T03:53:18.847+0000] {__init__.py:49} INFO - file_cache is only supported with oauth2client<4.0.0
[2024-08-30T03:53:20.791+0000] {logging_mixin.py:190} INFO - Downloading Nhóm 4 - Lê Duy Khang - 2152108.JPG: 100%.
[2024-08-30T03:53:20.794+0000] {logging_mixin.py:190} INFO - [2024-08-30T03:53:20.794+0000] {connectionpool.py:870} WARNING - Retrying (Retry(total=4, connect=None, read=None, redirect=None, status=None)) after connection broken by 'NewConnectionError('<urllib3.connection.HTTPConnection object at 0x7f0fd946c0b0>: Failed to establish a new connection: [Errno 111] Connection refused')': /drive-fetch?location=
[2024-08-30T03:53:21.195+0000] {logging_mixin.py:190} INFO - [2024-08-30T03:53:21.195+0000] {connectionpool.py:870} WARNING - Retrying (Retry(total=3, connect=None, read=None, redirect=None, status=None)) after connection broken by 'NewConnectionError('<urllib3.connection.HTTPConnection object at 0x7f0fd946d7f0>: Failed to establish a new connection: [Errno 111] Connection refused')': /drive-fetch?location=
[2024-08-30T03:53:21.996+0000] {logging_mixin.py:190} INFO - [2024-08-30T03:53:21.996+0000] {connectionpool.py:870} WARNING - Retrying (Retry(total=2, connect=None, read=None, redirect=None, status=None)) after connection broken by 'NewConnectionError('<urllib3.connection.HTTPConnection object at 0x7f0fd946df70>: Failed to establish a new connection: [Errno 111] Connection refused')': /drive-fetch?location=
[2024-08-30T03:53:23.599+0000] {logging_mixin.py:190} INFO - [2024-08-30T03:53:23.598+0000] {connectionpool.py:870} WARNING - Retrying (Retry(total=1, connect=None, read=None, redirect=None, status=None)) after connection broken by 'NewConnectionError('<urllib3.connection.HTTPConnection object at 0x7f0fd946e2a0>: Failed to establish a new connection: [Errno 111] Connection refused')': /drive-fetch?location=
[2024-08-30T03:53:26.802+0000] {logging_mixin.py:190} INFO - [2024-08-30T03:53:26.802+0000] {connectionpool.py:870} WARNING - Retrying (Retry(total=0, connect=None, read=None, redirect=None, status=None)) after connection broken by 'NewConnectionError('<urllib3.connection.HTTPConnection object at 0x7f0fd946e960>: Failed to establish a new connection: [Errno 111] Connection refused')': /drive-fetch?location=
[2024-08-30T03:53:26.818+0000] {logging_mixin.py:190} INFO - [2024-08-30T03:53:26.803+0000] {dagbag.py:386} ERROR - Failed to import: /opt/airflow/dags/download_dag.py
Traceback (most recent call last):
  File "/home/airflow/.local/lib/python3.12/site-packages/urllib3/connection.py", line 196, in _new_conn
    sock = connection.create_connection(
           ^^^^^^^^^^^^^^^^^^^^^^^^^^^^^
  File "/home/airflow/.local/lib/python3.12/site-packages/urllib3/util/connection.py", line 85, in create_connection
    raise err
  File "/home/airflow/.local/lib/python3.12/site-packages/urllib3/util/connection.py", line 73, in create_connection
    sock.connect(sa)
ConnectionRefusedError: [Errno 111] Connection refused

The above exception was the direct cause of the following exception:

Traceback (most recent call last):
  File "/home/airflow/.local/lib/python3.12/site-packages/urllib3/connectionpool.py", line 789, in urlopen
    response = self._make_request(
               ^^^^^^^^^^^^^^^^^^^
  File "/home/airflow/.local/lib/python3.12/site-packages/urllib3/connectionpool.py", line 495, in _make_request
    conn.request(
  File "/home/airflow/.local/lib/python3.12/site-packages/urllib3/connection.py", line 398, in request
    self.endheaders()
  File "/usr/local/lib/python3.12/http/client.py", line 1331, in endheaders
    self._send_output(message_body, encode_chunked=encode_chunked)
  File "/usr/local/lib/python3.12/http/client.py", line 1091, in _send_output
    self.send(msg)
  File "/usr/local/lib/python3.12/http/client.py", line 1035, in send
    self.connect()
  File "/home/airflow/.local/lib/python3.12/site-packages/urllib3/connection.py", line 236, in connect
    self.sock = self._new_conn()
                ^^^^^^^^^^^^^^^^
  File "/home/airflow/.local/lib/python3.12/site-packages/urllib3/connection.py", line 211, in _new_conn
    raise NewConnectionError(
urllib3.exceptions.NewConnectionError: <urllib3.connection.HTTPConnection object at 0x7f0fd946ef90>: Failed to establish a new connection: [Errno 111] Connection refused

The above exception was the direct cause of the following exception:

Traceback (most recent call last):
  File "/home/airflow/.local/lib/python3.12/site-packages/airflow/models/dagbag.py", line 382, in parse
    loader.exec_module(new_module)
  File "<frozen importlib._bootstrap_external>", line 995, in exec_module
  File "<frozen importlib._bootstrap>", line 488, in _call_with_frames_removed
  File "/opt/airflow/dags/download_dag.py", line 111, in <module>
    python_callable=download_to_minio(authenticate_gdrive(), FOLDER_ID),
                    ^^^^^^^^^^^^^^^^^^^^^^^^^^^^^^^^^^^^^^^^^^^^^^^^^^^
  File "/opt/airflow/dags/download_dag.py", line 78, in download_to_minio
    minio_client.put_object(
  File "/home/airflow/.local/lib/python3.12/site-packages/minio/api.py", line 1922, in put_object
    raise exc
  File "/home/airflow/.local/lib/python3.12/site-packages/minio/api.py", line 1868, in put_object
    return self._put_object(
           ^^^^^^^^^^^^^^^^^
  File "/home/airflow/.local/lib/python3.12/site-packages/minio/api.py", line 1707, in _put_object
    response = self._execute(
               ^^^^^^^^^^^^^^
  File "/home/airflow/.local/lib/python3.12/site-packages/minio/api.py", line 437, in _execute
    region = self._get_region(bucket_name)
             ^^^^^^^^^^^^^^^^^^^^^^^^^^^^^
  File "/home/airflow/.local/lib/python3.12/site-packages/minio/api.py", line 494, in _get_region
    response = self._url_open(
               ^^^^^^^^^^^^^^^
  File "/home/airflow/.local/lib/python3.12/site-packages/minio/api.py", line 302, in _url_open
    response = self._http.urlopen(
               ^^^^^^^^^^^^^^^^^^^
  File "/home/airflow/.local/lib/python3.12/site-packages/urllib3/poolmanager.py", line 443, in urlopen
    response = conn.urlopen(method, u.request_uri, **kw)
               ^^^^^^^^^^^^^^^^^^^^^^^^^^^^^^^^^^^^^^^^^
  File "/home/airflow/.local/lib/python3.12/site-packages/urllib3/connectionpool.py", line 873, in urlopen
    return self.urlopen(
           ^^^^^^^^^^^^^
  File "/home/airflow/.local/lib/python3.12/site-packages/urllib3/connectionpool.py", line 873, in urlopen
    return self.urlopen(
           ^^^^^^^^^^^^^
  File "/home/airflow/.local/lib/python3.12/site-packages/urllib3/connectionpool.py", line 873, in urlopen
    return self.urlopen(
           ^^^^^^^^^^^^^
  [Previous line repeated 2 more times]
  File "/home/airflow/.local/lib/python3.12/site-packages/urllib3/connectionpool.py", line 843, in urlopen
    retries = retries.increment(
              ^^^^^^^^^^^^^^^^^^
  File "/home/airflow/.local/lib/python3.12/site-packages/urllib3/util/retry.py", line 519, in increment
    raise MaxRetryError(_pool, url, reason) from reason  # type: ignore[arg-type]
    ^^^^^^^^^^^^^^^^^^^^^^^^^^^^^^^^^^^^^^^^^^^^^^^^^^^
urllib3.exceptions.MaxRetryError: HTTPConnectionPool(host='localhost', port=9000): Max retries exceeded with url: /drive-fetch?location= (Caused by NewConnectionError('<urllib3.connection.HTTPConnection object at 0x7f0fd946ef90>: Failed to establish a new connection: [Errno 111] Connection refused'))
[2024-08-30T03:53:26.819+0000] {processor.py:927} WARNING - No viable dags retrieved from /opt/airflow/dags/download_dag.py
[2024-08-30T03:53:26.834+0000] {processor.py:208} INFO - Processing /opt/airflow/dags/download_dag.py took 8.167 seconds
[2024-08-30T03:53:57.792+0000] {processor.py:186} INFO - Started process (PID=1046) to work on /opt/airflow/dags/download_dag.py
[2024-08-30T03:53:57.793+0000] {processor.py:914} INFO - Processing file /opt/airflow/dags/download_dag.py for tasks to queue
[2024-08-30T03:53:57.795+0000] {logging_mixin.py:190} INFO - [2024-08-30T03:53:57.794+0000] {dagbag.py:587} INFO - Filling up the DagBag from /opt/airflow/dags/download_dag.py
[2024-08-30T03:53:57.944+0000] {logging_mixin.py:190} INFO - [2024-08-30T03:53:57.944+0000] {__init__.py:49} INFO - file_cache is only supported with oauth2client<4.0.0
[2024-08-30T03:54:00.819+0000] {logging_mixin.py:190} INFO - Downloading Nhóm 4 - Lê Duy Khang - 2152108.JPG: 100%.
[2024-08-30T03:54:00.821+0000] {logging_mixin.py:190} INFO - [2024-08-30T03:54:00.820+0000] {connectionpool.py:870} WARNING - Retrying (Retry(total=4, connect=None, read=None, redirect=None, status=None)) after connection broken by 'NewConnectionError('<urllib3.connection.HTTPConnection object at 0x7f0fd9457620>: Failed to establish a new connection: [Errno 111] Connection refused')': /drive-fetch?location=
[2024-08-30T03:54:01.222+0000] {logging_mixin.py:190} INFO - [2024-08-30T03:54:01.222+0000] {connectionpool.py:870} WARNING - Retrying (Retry(total=3, connect=None, read=None, redirect=None, status=None)) after connection broken by 'NewConnectionError('<urllib3.connection.HTTPConnection object at 0x7f0fd9475910>: Failed to establish a new connection: [Errno 111] Connection refused')': /drive-fetch?location=
[2024-08-30T03:54:02.024+0000] {logging_mixin.py:190} INFO - [2024-08-30T03:54:02.023+0000] {connectionpool.py:870} WARNING - Retrying (Retry(total=2, connect=None, read=None, redirect=None, status=None)) after connection broken by 'NewConnectionError('<urllib3.connection.HTTPConnection object at 0x7f0fd9475e80>: Failed to establish a new connection: [Errno 111] Connection refused')': /drive-fetch?location=
[2024-08-30T03:54:03.627+0000] {logging_mixin.py:190} INFO - [2024-08-30T03:54:03.627+0000] {connectionpool.py:870} WARNING - Retrying (Retry(total=1, connect=None, read=None, redirect=None, status=None)) after connection broken by 'NewConnectionError('<urllib3.connection.HTTPConnection object at 0x7f0fd94762a0>: Failed to establish a new connection: [Errno 111] Connection refused')': /drive-fetch?location=
[2024-08-30T03:54:06.830+0000] {logging_mixin.py:190} INFO - [2024-08-30T03:54:06.829+0000] {connectionpool.py:870} WARNING - Retrying (Retry(total=0, connect=None, read=None, redirect=None, status=None)) after connection broken by 'NewConnectionError('<urllib3.connection.HTTPConnection object at 0x7f0fd9476990>: Failed to establish a new connection: [Errno 111] Connection refused')': /drive-fetch?location=
[2024-08-30T03:54:06.946+0000] {logging_mixin.py:190} INFO - [2024-08-30T03:54:06.842+0000] {dagbag.py:386} ERROR - Failed to import: /opt/airflow/dags/download_dag.py
Traceback (most recent call last):
  File "/home/airflow/.local/lib/python3.12/site-packages/urllib3/connection.py", line 196, in _new_conn
    sock = connection.create_connection(
           ^^^^^^^^^^^^^^^^^^^^^^^^^^^^^
  File "/home/airflow/.local/lib/python3.12/site-packages/urllib3/util/connection.py", line 85, in create_connection
    raise err
  File "/home/airflow/.local/lib/python3.12/site-packages/urllib3/util/connection.py", line 73, in create_connection
    sock.connect(sa)
ConnectionRefusedError: [Errno 111] Connection refused

The above exception was the direct cause of the following exception:

Traceback (most recent call last):
  File "/home/airflow/.local/lib/python3.12/site-packages/urllib3/connectionpool.py", line 789, in urlopen
    response = self._make_request(
               ^^^^^^^^^^^^^^^^^^^
  File "/home/airflow/.local/lib/python3.12/site-packages/urllib3/connectionpool.py", line 495, in _make_request
    conn.request(
  File "/home/airflow/.local/lib/python3.12/site-packages/urllib3/connection.py", line 398, in request
    self.endheaders()
  File "/usr/local/lib/python3.12/http/client.py", line 1331, in endheaders
    self._send_output(message_body, encode_chunked=encode_chunked)
  File "/usr/local/lib/python3.12/http/client.py", line 1091, in _send_output
    self.send(msg)
  File "/usr/local/lib/python3.12/http/client.py", line 1035, in send
    self.connect()
  File "/home/airflow/.local/lib/python3.12/site-packages/urllib3/connection.py", line 236, in connect
    self.sock = self._new_conn()
                ^^^^^^^^^^^^^^^^
  File "/home/airflow/.local/lib/python3.12/site-packages/urllib3/connection.py", line 211, in _new_conn
    raise NewConnectionError(
urllib3.exceptions.NewConnectionError: <urllib3.connection.HTTPConnection object at 0x7f0fd9477080>: Failed to establish a new connection: [Errno 111] Connection refused

The above exception was the direct cause of the following exception:

Traceback (most recent call last):
  File "/home/airflow/.local/lib/python3.12/site-packages/airflow/models/dagbag.py", line 382, in parse
    loader.exec_module(new_module)
  File "<frozen importlib._bootstrap_external>", line 995, in exec_module
  File "<frozen importlib._bootstrap>", line 488, in _call_with_frames_removed
  File "/opt/airflow/dags/download_dag.py", line 111, in <module>
    python_callable=download_to_minio(authenticate_gdrive(), FOLDER_ID),
                    ^^^^^^^^^^^^^^^^^^^^^^^^^^^^^^^^^^^^^^^^^^^^^^^^^^^
  File "/opt/airflow/dags/download_dag.py", line 78, in download_to_minio
    minio_client.put_object(
  File "/home/airflow/.local/lib/python3.12/site-packages/minio/api.py", line 1922, in put_object
    raise exc
  File "/home/airflow/.local/lib/python3.12/site-packages/minio/api.py", line 1868, in put_object
    return self._put_object(
           ^^^^^^^^^^^^^^^^^
  File "/home/airflow/.local/lib/python3.12/site-packages/minio/api.py", line 1707, in _put_object
    response = self._execute(
               ^^^^^^^^^^^^^^
  File "/home/airflow/.local/lib/python3.12/site-packages/minio/api.py", line 437, in _execute
    region = self._get_region(bucket_name)
             ^^^^^^^^^^^^^^^^^^^^^^^^^^^^^
  File "/home/airflow/.local/lib/python3.12/site-packages/minio/api.py", line 494, in _get_region
    response = self._url_open(
               ^^^^^^^^^^^^^^^
  File "/home/airflow/.local/lib/python3.12/site-packages/minio/api.py", line 302, in _url_open
    response = self._http.urlopen(
               ^^^^^^^^^^^^^^^^^^^
  File "/home/airflow/.local/lib/python3.12/site-packages/urllib3/poolmanager.py", line 443, in urlopen
    response = conn.urlopen(method, u.request_uri, **kw)
               ^^^^^^^^^^^^^^^^^^^^^^^^^^^^^^^^^^^^^^^^^
  File "/home/airflow/.local/lib/python3.12/site-packages/urllib3/connectionpool.py", line 873, in urlopen
    return self.urlopen(
           ^^^^^^^^^^^^^
  File "/home/airflow/.local/lib/python3.12/site-packages/urllib3/connectionpool.py", line 873, in urlopen
    return self.urlopen(
           ^^^^^^^^^^^^^
  File "/home/airflow/.local/lib/python3.12/site-packages/urllib3/connectionpool.py", line 873, in urlopen
    return self.urlopen(
           ^^^^^^^^^^^^^
  [Previous line repeated 2 more times]
  File "/home/airflow/.local/lib/python3.12/site-packages/urllib3/connectionpool.py", line 843, in urlopen
    retries = retries.increment(
              ^^^^^^^^^^^^^^^^^^
  File "/home/airflow/.local/lib/python3.12/site-packages/urllib3/util/retry.py", line 519, in increment
    raise MaxRetryError(_pool, url, reason) from reason  # type: ignore[arg-type]
    ^^^^^^^^^^^^^^^^^^^^^^^^^^^^^^^^^^^^^^^^^^^^^^^^^^^
urllib3.exceptions.MaxRetryError: HTTPConnectionPool(host='localhost', port=9000): Max retries exceeded with url: /drive-fetch?location= (Caused by NewConnectionError('<urllib3.connection.HTTPConnection object at 0x7f0fd9477080>: Failed to establish a new connection: [Errno 111] Connection refused'))
[2024-08-30T03:54:06.950+0000] {processor.py:927} WARNING - No viable dags retrieved from /opt/airflow/dags/download_dag.py
[2024-08-30T03:54:06.981+0000] {processor.py:208} INFO - Processing /opt/airflow/dags/download_dag.py took 9.195 seconds
[2024-08-30T03:54:37.489+0000] {processor.py:186} INFO - Started process (PID=1129) to work on /opt/airflow/dags/download_dag.py
[2024-08-30T03:54:37.490+0000] {processor.py:914} INFO - Processing file /opt/airflow/dags/download_dag.py for tasks to queue
[2024-08-30T03:54:37.491+0000] {logging_mixin.py:190} INFO - [2024-08-30T03:54:37.491+0000] {dagbag.py:587} INFO - Filling up the DagBag from /opt/airflow/dags/download_dag.py
[2024-08-30T03:54:37.644+0000] {logging_mixin.py:190} INFO - [2024-08-30T03:54:37.644+0000] {__init__.py:49} INFO - file_cache is only supported with oauth2client<4.0.0
[2024-08-30T03:54:40.781+0000] {logging_mixin.py:190} INFO - Downloading Nhóm 4 - Lê Duy Khang - 2152108.JPG: 100%.
[2024-08-30T03:54:40.784+0000] {logging_mixin.py:190} INFO - [2024-08-30T03:54:40.783+0000] {connectionpool.py:870} WARNING - Retrying (Retry(total=4, connect=None, read=None, redirect=None, status=None)) after connection broken by 'NewConnectionError('<urllib3.connection.HTTPConnection object at 0x7f0fd93fc650>: Failed to establish a new connection: [Errno 111] Connection refused')': /drive-fetch?location=
[2024-08-30T03:54:41.185+0000] {logging_mixin.py:190} INFO - [2024-08-30T03:54:41.185+0000] {connectionpool.py:870} WARNING - Retrying (Retry(total=3, connect=None, read=None, redirect=None, status=None)) after connection broken by 'NewConnectionError('<urllib3.connection.HTTPConnection object at 0x7f0fd9474140>: Failed to establish a new connection: [Errno 111] Connection refused')': /drive-fetch?location=
[2024-08-30T03:54:41.988+0000] {logging_mixin.py:190} INFO - [2024-08-30T03:54:41.987+0000] {connectionpool.py:870} WARNING - Retrying (Retry(total=2, connect=None, read=None, redirect=None, status=None)) after connection broken by 'NewConnectionError('<urllib3.connection.HTTPConnection object at 0x7f0fd9475ee0>: Failed to establish a new connection: [Errno 111] Connection refused')': /drive-fetch?location=
[2024-08-30T03:54:43.592+0000] {logging_mixin.py:190} INFO - [2024-08-30T03:54:43.591+0000] {connectionpool.py:870} WARNING - Retrying (Retry(total=1, connect=None, read=None, redirect=None, status=None)) after connection broken by 'NewConnectionError('<urllib3.connection.HTTPConnection object at 0x7f0fd9476360>: Failed to establish a new connection: [Errno 111] Connection refused')': /drive-fetch?location=
