[2024-09-05T09:58:20.101+0000] {processor.py:186} INFO - Started process (PID=66) to work on /opt/airflow/dags/download_dag.py
[2024-09-05T09:58:20.104+0000] {processor.py:914} INFO - Processing file /opt/airflow/dags/download_dag.py for tasks to queue
[2024-09-05T09:58:20.112+0000] {logging_mixin.py:190} INFO - [2024-09-05T09:58:20.111+0000] {dagbag.py:587} INFO - Filling up the DagBag from /opt/airflow/dags/download_dag.py
[2024-09-05T09:58:20.863+0000] {logging_mixin.py:190} INFO - [2024-09-05T09:58:20.863+0000] {__init__.py:49} INFO - file_cache is only supported with oauth2client<4.0.0
[2024-09-05T09:58:23.037+0000] {logging_mixin.py:190} INFO - Downloading cat1.png: 100%.
[2024-09-05T09:58:23.043+0000] {logging_mixin.py:190} INFO - [2024-09-05T09:58:23.043+0000] {connectionpool.py:870} WARNING - Retrying (Retry(total=4, connect=None, read=None, redirect=None, status=None)) after connection broken by 'NewConnectionError('<urllib3.connection.HTTPConnection object at 0x7f49d74d2060>: Failed to establish a new connection: [Errno 111] Connection refused')': /drive-fetch?location=
[2024-09-05T09:58:23.445+0000] {logging_mixin.py:190} INFO - [2024-09-05T09:58:23.445+0000] {connectionpool.py:870} WARNING - Retrying (Retry(total=3, connect=None, read=None, redirect=None, status=None)) after connection broken by 'NewConnectionError('<urllib3.connection.HTTPConnection object at 0x7f49d721c500>: Failed to establish a new connection: [Errno 111] Connection refused')': /drive-fetch?location=
[2024-09-05T09:58:24.247+0000] {logging_mixin.py:190} INFO - [2024-09-05T09:58:24.246+0000] {connectionpool.py:870} WARNING - Retrying (Retry(total=2, connect=None, read=None, redirect=None, status=None)) after connection broken by 'NewConnectionError('<urllib3.connection.HTTPConnection object at 0x7f49d721f530>: Failed to establish a new connection: [Errno 111] Connection refused')': /drive-fetch?location=
[2024-09-05T09:58:25.850+0000] {logging_mixin.py:190} INFO - [2024-09-05T09:58:25.850+0000] {connectionpool.py:870} WARNING - Retrying (Retry(total=1, connect=None, read=None, redirect=None, status=None)) after connection broken by 'NewConnectionError('<urllib3.connection.HTTPConnection object at 0x7f49d721ccb0>: Failed to establish a new connection: [Errno 111] Connection refused')': /drive-fetch?location=
[2024-09-05T09:58:29.052+0000] {logging_mixin.py:190} INFO - [2024-09-05T09:58:29.052+0000] {connectionpool.py:870} WARNING - Retrying (Retry(total=0, connect=None, read=None, redirect=None, status=None)) after connection broken by 'NewConnectionError('<urllib3.connection.HTTPConnection object at 0x7f49d721fec0>: Failed to establish a new connection: [Errno 111] Connection refused')': /drive-fetch?location=
[2024-09-05T09:58:29.069+0000] {logging_mixin.py:190} INFO - [2024-09-05T09:58:29.054+0000] {dagbag.py:386} ERROR - Failed to import: /opt/airflow/dags/download_dag.py
Traceback (most recent call last):
  File "/home/airflow/.local/lib/python3.12/site-packages/urllib3/connection.py", line 196, in _new_conn
    sock = connection.create_connection(
           ^^^^^^^^^^^^^^^^^^^^^^^^^^^^^
  File "/home/airflow/.local/lib/python3.12/site-packages/urllib3/util/connection.py", line 85, in create_connection
    raise err
  File "/home/airflow/.local/lib/python3.12/site-packages/urllib3/util/connection.py", line 73, in create_connection
    sock.connect(sa)
ConnectionRefusedError: [Errno 111] Connection refused

The above exception was the direct cause of the following exception:

Traceback (most recent call last):
  File "/home/airflow/.local/lib/python3.12/site-packages/urllib3/connectionpool.py", line 789, in urlopen
    response = self._make_request(
               ^^^^^^^^^^^^^^^^^^^
  File "/home/airflow/.local/lib/python3.12/site-packages/urllib3/connectionpool.py", line 495, in _make_request
    conn.request(
  File "/home/airflow/.local/lib/python3.12/site-packages/urllib3/connection.py", line 398, in request
    self.endheaders()
  File "/usr/local/lib/python3.12/http/client.py", line 1331, in endheaders
    self._send_output(message_body, encode_chunked=encode_chunked)
  File "/usr/local/lib/python3.12/http/client.py", line 1091, in _send_output
    self.send(msg)
  File "/usr/local/lib/python3.12/http/client.py", line 1035, in send
    self.connect()
  File "/home/airflow/.local/lib/python3.12/site-packages/urllib3/connection.py", line 236, in connect
    self.sock = self._new_conn()
                ^^^^^^^^^^^^^^^^
  File "/home/airflow/.local/lib/python3.12/site-packages/urllib3/connection.py", line 211, in _new_conn
    raise NewConnectionError(
urllib3.exceptions.NewConnectionError: <urllib3.connection.HTTPConnection object at 0x7f49d7220500>: Failed to establish a new connection: [Errno 111] Connection refused

The above exception was the direct cause of the following exception:

Traceback (most recent call last):
  File "/home/airflow/.local/lib/python3.12/site-packages/airflow/models/dagbag.py", line 382, in parse
    loader.exec_module(new_module)
  File "<frozen importlib._bootstrap_external>", line 995, in exec_module
  File "<frozen importlib._bootstrap>", line 488, in _call_with_frames_removed
  File "/opt/airflow/dags/download_dag.py", line 111, in <module>
    python_callable=download_to_minio(authenticate_gdrive(), FOLDER_ID),
                    ^^^^^^^^^^^^^^^^^^^^^^^^^^^^^^^^^^^^^^^^^^^^^^^^^^^
  File "/opt/airflow/dags/download_dag.py", line 78, in download_to_minio
    minio_client.put_object(
  File "/home/airflow/.local/lib/python3.12/site-packages/minio/api.py", line 1922, in put_object
    raise exc
  File "/home/airflow/.local/lib/python3.12/site-packages/minio/api.py", line 1868, in put_object
    return self._put_object(
           ^^^^^^^^^^^^^^^^^
  File "/home/airflow/.local/lib/python3.12/site-packages/minio/api.py", line 1707, in _put_object
    response = self._execute(
               ^^^^^^^^^^^^^^
  File "/home/airflow/.local/lib/python3.12/site-packages/minio/api.py", line 437, in _execute
    region = self._get_region(bucket_name)
             ^^^^^^^^^^^^^^^^^^^^^^^^^^^^^
  File "/home/airflow/.local/lib/python3.12/site-packages/minio/api.py", line 494, in _get_region
    response = self._url_open(
               ^^^^^^^^^^^^^^^
  File "/home/airflow/.local/lib/python3.12/site-packages/minio/api.py", line 302, in _url_open
    response = self._http.urlopen(
               ^^^^^^^^^^^^^^^^^^^
  File "/home/airflow/.local/lib/python3.12/site-packages/urllib3/poolmanager.py", line 443, in urlopen
    response = conn.urlopen(method, u.request_uri, **kw)
               ^^^^^^^^^^^^^^^^^^^^^^^^^^^^^^^^^^^^^^^^^
  File "/home/airflow/.local/lib/python3.12/site-packages/urllib3/connectionpool.py", line 873, in urlopen
    return self.urlopen(
           ^^^^^^^^^^^^^
  File "/home/airflow/.local/lib/python3.12/site-packages/urllib3/connectionpool.py", line 873, in urlopen
    return self.urlopen(
           ^^^^^^^^^^^^^
  File "/home/airflow/.local/lib/python3.12/site-packages/urllib3/connectionpool.py", line 873, in urlopen
    return self.urlopen(
           ^^^^^^^^^^^^^
  [Previous line repeated 2 more times]
  File "/home/airflow/.local/lib/python3.12/site-packages/urllib3/connectionpool.py", line 843, in urlopen
    retries = retries.increment(
              ^^^^^^^^^^^^^^^^^^
  File "/home/airflow/.local/lib/python3.12/site-packages/urllib3/util/retry.py", line 519, in increment
    raise MaxRetryError(_pool, url, reason) from reason  # type: ignore[arg-type]
    ^^^^^^^^^^^^^^^^^^^^^^^^^^^^^^^^^^^^^^^^^^^^^^^^^^^
urllib3.exceptions.MaxRetryError: HTTPConnectionPool(host='localhost', port=9000): Max retries exceeded with url: /drive-fetch?location= (Caused by NewConnectionError('<urllib3.connection.HTTPConnection object at 0x7f49d7220500>: Failed to establish a new connection: [Errno 111] Connection refused'))
[2024-09-05T09:58:29.072+0000] {processor.py:927} WARNING - No viable dags retrieved from /opt/airflow/dags/download_dag.py
[2024-09-05T09:58:29.097+0000] {processor.py:208} INFO - Processing /opt/airflow/dags/download_dag.py took 9.012 seconds
[2024-09-05T09:58:59.804+0000] {processor.py:186} INFO - Started process (PID=168) to work on /opt/airflow/dags/download_dag.py
[2024-09-05T09:58:59.806+0000] {processor.py:914} INFO - Processing file /opt/airflow/dags/download_dag.py for tasks to queue
[2024-09-05T09:58:59.809+0000] {logging_mixin.py:190} INFO - [2024-09-05T09:58:59.809+0000] {dagbag.py:587} INFO - Filling up the DagBag from /opt/airflow/dags/download_dag.py
[2024-09-05T09:59:00.061+0000] {logging_mixin.py:190} INFO - [2024-09-05T09:59:00.061+0000] {__init__.py:49} INFO - file_cache is only supported with oauth2client<4.0.0
[2024-09-05T09:59:04.332+0000] {logging_mixin.py:190} INFO - Downloading cat1.png: 100%.
[2024-09-05T09:59:04.335+0000] {logging_mixin.py:190} INFO - [2024-09-05T09:59:04.334+0000] {connectionpool.py:870} WARNING - Retrying (Retry(total=4, connect=None, read=None, redirect=None, status=None)) after connection broken by 'NewConnectionError('<urllib3.connection.HTTPConnection object at 0x7f49d6f7bd40>: Failed to establish a new connection: [Errno 111] Connection refused')': /drive-fetch?location=
[2024-09-05T09:59:04.736+0000] {logging_mixin.py:190} INFO - [2024-09-05T09:59:04.736+0000] {connectionpool.py:870} WARNING - Retrying (Retry(total=3, connect=None, read=None, redirect=None, status=None)) after connection broken by 'NewConnectionError('<urllib3.connection.HTTPConnection object at 0x7f49d6fac7d0>: Failed to establish a new connection: [Errno 111] Connection refused')': /drive-fetch?location=
[2024-09-05T09:59:05.538+0000] {logging_mixin.py:190} INFO - [2024-09-05T09:59:05.538+0000] {connectionpool.py:870} WARNING - Retrying (Retry(total=2, connect=None, read=None, redirect=None, status=None)) after connection broken by 'NewConnectionError('<urllib3.connection.HTTPConnection object at 0x7f49d6facd40>: Failed to establish a new connection: [Errno 111] Connection refused')': /drive-fetch?location=
[2024-09-05T09:59:07.140+0000] {logging_mixin.py:190} INFO - [2024-09-05T09:59:07.139+0000] {connectionpool.py:870} WARNING - Retrying (Retry(total=1, connect=None, read=None, redirect=None, status=None)) after connection broken by 'NewConnectionError('<urllib3.connection.HTTPConnection object at 0x7f49d6fad400>: Failed to establish a new connection: [Errno 111] Connection refused')': /drive-fetch?location=
[2024-09-05T09:59:10.342+0000] {logging_mixin.py:190} INFO - [2024-09-05T09:59:10.342+0000] {connectionpool.py:870} WARNING - Retrying (Retry(total=0, connect=None, read=None, redirect=None, status=None)) after connection broken by 'NewConnectionError('<urllib3.connection.HTTPConnection object at 0x7f49d6fad9d0>: Failed to establish a new connection: [Errno 111] Connection refused')': /drive-fetch?location=
[2024-09-05T09:59:10.352+0000] {logging_mixin.py:190} INFO - [2024-09-05T09:59:10.345+0000] {dagbag.py:386} ERROR - Failed to import: /opt/airflow/dags/download_dag.py
Traceback (most recent call last):
  File "/home/airflow/.local/lib/python3.12/site-packages/urllib3/connection.py", line 196, in _new_conn
    sock = connection.create_connection(
           ^^^^^^^^^^^^^^^^^^^^^^^^^^^^^
  File "/home/airflow/.local/lib/python3.12/site-packages/urllib3/util/connection.py", line 85, in create_connection
    raise err
  File "/home/airflow/.local/lib/python3.12/site-packages/urllib3/util/connection.py", line 73, in create_connection
    sock.connect(sa)
ConnectionRefusedError: [Errno 111] Connection refused

The above exception was the direct cause of the following exception:

Traceback (most recent call last):
  File "/home/airflow/.local/lib/python3.12/site-packages/urllib3/connectionpool.py", line 789, in urlopen
    response = self._make_request(
               ^^^^^^^^^^^^^^^^^^^
  File "/home/airflow/.local/lib/python3.12/site-packages/urllib3/connectionpool.py", line 495, in _make_request
    conn.request(
  File "/home/airflow/.local/lib/python3.12/site-packages/urllib3/connection.py", line 398, in request
    self.endheaders()
  File "/usr/local/lib/python3.12/http/client.py", line 1331, in endheaders
    self._send_output(message_body, encode_chunked=encode_chunked)
  File "/usr/local/lib/python3.12/http/client.py", line 1091, in _send_output
    self.send(msg)
  File "/usr/local/lib/python3.12/http/client.py", line 1035, in send
    self.connect()
  File "/home/airflow/.local/lib/python3.12/site-packages/urllib3/connection.py", line 236, in connect
    self.sock = self._new_conn()
                ^^^^^^^^^^^^^^^^
  File "/home/airflow/.local/lib/python3.12/site-packages/urllib3/connection.py", line 211, in _new_conn
    raise NewConnectionError(
urllib3.exceptions.NewConnectionError: <urllib3.connection.HTTPConnection object at 0x7f49d6fae090>: Failed to establish a new connection: [Errno 111] Connection refused

The above exception was the direct cause of the following exception:

Traceback (most recent call last):
  File "/home/airflow/.local/lib/python3.12/site-packages/airflow/models/dagbag.py", line 382, in parse
    loader.exec_module(new_module)
  File "<frozen importlib._bootstrap_external>", line 995, in exec_module
  File "<frozen importlib._bootstrap>", line 488, in _call_with_frames_removed
  File "/opt/airflow/dags/download_dag.py", line 111, in <module>
    python_callable=download_to_minio(authenticate_gdrive(), FOLDER_ID),
                    ^^^^^^^^^^^^^^^^^^^^^^^^^^^^^^^^^^^^^^^^^^^^^^^^^^^
  File "/opt/airflow/dags/download_dag.py", line 78, in download_to_minio
    minio_client.put_object(
  File "/home/airflow/.local/lib/python3.12/site-packages/minio/api.py", line 1922, in put_object
    raise exc
  File "/home/airflow/.local/lib/python3.12/site-packages/minio/api.py", line 1868, in put_object
    return self._put_object(
           ^^^^^^^^^^^^^^^^^
  File "/home/airflow/.local/lib/python3.12/site-packages/minio/api.py", line 1707, in _put_object
    response = self._execute(
               ^^^^^^^^^^^^^^
  File "/home/airflow/.local/lib/python3.12/site-packages/minio/api.py", line 437, in _execute
    region = self._get_region(bucket_name)
             ^^^^^^^^^^^^^^^^^^^^^^^^^^^^^
  File "/home/airflow/.local/lib/python3.12/site-packages/minio/api.py", line 494, in _get_region
    response = self._url_open(
               ^^^^^^^^^^^^^^^
  File "/home/airflow/.local/lib/python3.12/site-packages/minio/api.py", line 302, in _url_open
    response = self._http.urlopen(
               ^^^^^^^^^^^^^^^^^^^
  File "/home/airflow/.local/lib/python3.12/site-packages/urllib3/poolmanager.py", line 443, in urlopen
    response = conn.urlopen(method, u.request_uri, **kw)
               ^^^^^^^^^^^^^^^^^^^^^^^^^^^^^^^^^^^^^^^^^
  File "/home/airflow/.local/lib/python3.12/site-packages/urllib3/connectionpool.py", line 873, in urlopen
    return self.urlopen(
           ^^^^^^^^^^^^^
  File "/home/airflow/.local/lib/python3.12/site-packages/urllib3/connectionpool.py", line 873, in urlopen
    return self.urlopen(
           ^^^^^^^^^^^^^
  File "/home/airflow/.local/lib/python3.12/site-packages/urllib3/connectionpool.py", line 873, in urlopen
    return self.urlopen(
           ^^^^^^^^^^^^^
  [Previous line repeated 2 more times]
  File "/home/airflow/.local/lib/python3.12/site-packages/urllib3/connectionpool.py", line 843, in urlopen
    retries = retries.increment(
              ^^^^^^^^^^^^^^^^^^
  File "/home/airflow/.local/lib/python3.12/site-packages/urllib3/util/retry.py", line 519, in increment
    raise MaxRetryError(_pool, url, reason) from reason  # type: ignore[arg-type]
    ^^^^^^^^^^^^^^^^^^^^^^^^^^^^^^^^^^^^^^^^^^^^^^^^^^^
urllib3.exceptions.MaxRetryError: HTTPConnectionPool(host='localhost', port=9000): Max retries exceeded with url: /drive-fetch?location= (Caused by NewConnectionError('<urllib3.connection.HTTPConnection object at 0x7f49d6fae090>: Failed to establish a new connection: [Errno 111] Connection refused'))
[2024-09-05T09:59:10.354+0000] {processor.py:927} WARNING - No viable dags retrieved from /opt/airflow/dags/download_dag.py
[2024-09-05T09:59:10.382+0000] {processor.py:208} INFO - Processing /opt/airflow/dags/download_dag.py took 10.584 seconds
[2024-09-05T09:59:40.937+0000] {processor.py:186} INFO - Started process (PID=254) to work on /opt/airflow/dags/download_dag.py
[2024-09-05T09:59:40.939+0000] {processor.py:914} INFO - Processing file /opt/airflow/dags/download_dag.py for tasks to queue
[2024-09-05T09:59:40.942+0000] {logging_mixin.py:190} INFO - [2024-09-05T09:59:40.942+0000] {dagbag.py:587} INFO - Filling up the DagBag from /opt/airflow/dags/download_dag.py
[2024-09-05T09:59:41.209+0000] {logging_mixin.py:190} INFO - [2024-09-05T09:59:41.209+0000] {__init__.py:49} INFO - file_cache is only supported with oauth2client<4.0.0
[2024-09-05T09:59:48.705+0000] {logging_mixin.py:190} INFO - Downloading cat1.png: 100%.
[2024-09-05T09:59:48.710+0000] {logging_mixin.py:190} INFO - [2024-09-05T09:59:48.709+0000] {connectionpool.py:870} WARNING - Retrying (Retry(total=4, connect=None, read=None, redirect=None, status=None)) after connection broken by 'NewConnectionError('<urllib3.connection.HTTPConnection object at 0x7f49d6f9b830>: Failed to establish a new connection: [Errno 111] Connection refused')': /drive-fetch?location=
[2024-09-05T09:59:49.112+0000] {logging_mixin.py:190} INFO - [2024-09-05T09:59:49.111+0000] {connectionpool.py:870} WARNING - Retrying (Retry(total=3, connect=None, read=None, redirect=None, status=None)) after connection broken by 'NewConnectionError('<urllib3.connection.HTTPConnection object at 0x7f499bdd4a40>: Failed to establish a new connection: [Errno 111] Connection refused')': /drive-fetch?location=
[2024-09-05T09:59:49.914+0000] {logging_mixin.py:190} INFO - [2024-09-05T09:59:49.914+0000] {connectionpool.py:870} WARNING - Retrying (Retry(total=2, connect=None, read=None, redirect=None, status=None)) after connection broken by 'NewConnectionError('<urllib3.connection.HTTPConnection object at 0x7f49d6fb4c20>: Failed to establish a new connection: [Errno 111] Connection refused')': /drive-fetch?location=
[2024-09-05T09:59:51.516+0000] {logging_mixin.py:190} INFO - [2024-09-05T09:59:51.515+0000] {connectionpool.py:870} WARNING - Retrying (Retry(total=1, connect=None, read=None, redirect=None, status=None)) after connection broken by 'NewConnectionError('<urllib3.connection.HTTPConnection object at 0x7f49d6fb5160>: Failed to establish a new connection: [Errno 111] Connection refused')': /drive-fetch?location=
[2024-09-05T09:59:54.717+0000] {logging_mixin.py:190} INFO - [2024-09-05T09:59:54.717+0000] {connectionpool.py:870} WARNING - Retrying (Retry(total=0, connect=None, read=None, redirect=None, status=None)) after connection broken by 'NewConnectionError('<urllib3.connection.HTTPConnection object at 0x7f49d6fb5ca0>: Failed to establish a new connection: [Errno 111] Connection refused')': /drive-fetch?location=
[2024-09-05T09:59:54.836+0000] {logging_mixin.py:190} INFO - [2024-09-05T09:59:54.755+0000] {dagbag.py:386} ERROR - Failed to import: /opt/airflow/dags/download_dag.py
Traceback (most recent call last):
  File "/home/airflow/.local/lib/python3.12/site-packages/urllib3/connection.py", line 196, in _new_conn
    sock = connection.create_connection(
           ^^^^^^^^^^^^^^^^^^^^^^^^^^^^^
  File "/home/airflow/.local/lib/python3.12/site-packages/urllib3/util/connection.py", line 85, in create_connection
    raise err
  File "/home/airflow/.local/lib/python3.12/site-packages/urllib3/util/connection.py", line 73, in create_connection
    sock.connect(sa)
ConnectionRefusedError: [Errno 111] Connection refused

The above exception was the direct cause of the following exception:

Traceback (most recent call last):
  File "/home/airflow/.local/lib/python3.12/site-packages/urllib3/connectionpool.py", line 789, in urlopen
    response = self._make_request(
               ^^^^^^^^^^^^^^^^^^^
  File "/home/airflow/.local/lib/python3.12/site-packages/urllib3/connectionpool.py", line 495, in _make_request
    conn.request(
  File "/home/airflow/.local/lib/python3.12/site-packages/urllib3/connection.py", line 398, in request
    self.endheaders()
  File "/usr/local/lib/python3.12/http/client.py", line 1331, in endheaders
    self._send_output(message_body, encode_chunked=encode_chunked)
  File "/usr/local/lib/python3.12/http/client.py", line 1091, in _send_output
    self.send(msg)
  File "/usr/local/lib/python3.12/http/client.py", line 1035, in send
    self.connect()
  File "/home/airflow/.local/lib/python3.12/site-packages/urllib3/connection.py", line 236, in connect
    self.sock = self._new_conn()
                ^^^^^^^^^^^^^^^^
  File "/home/airflow/.local/lib/python3.12/site-packages/urllib3/connection.py", line 211, in _new_conn
    raise NewConnectionError(
urllib3.exceptions.NewConnectionError: <urllib3.connection.HTTPConnection object at 0x7f49d6fb63f0>: Failed to establish a new connection: [Errno 111] Connection refused

The above exception was the direct cause of the following exception:

Traceback (most recent call last):
  File "/home/airflow/.local/lib/python3.12/site-packages/airflow/models/dagbag.py", line 382, in parse
    loader.exec_module(new_module)
  File "<frozen importlib._bootstrap_external>", line 995, in exec_module
  File "<frozen importlib._bootstrap>", line 488, in _call_with_frames_removed
  File "/opt/airflow/dags/download_dag.py", line 111, in <module>
    python_callable=download_to_minio(authenticate_gdrive(), FOLDER_ID),
                    ^^^^^^^^^^^^^^^^^^^^^^^^^^^^^^^^^^^^^^^^^^^^^^^^^^^
  File "/opt/airflow/dags/download_dag.py", line 78, in download_to_minio
    minio_client.put_object(
  File "/home/airflow/.local/lib/python3.12/site-packages/minio/api.py", line 1922, in put_object
    raise exc
  File "/home/airflow/.local/lib/python3.12/site-packages/minio/api.py", line 1868, in put_object
    return self._put_object(
           ^^^^^^^^^^^^^^^^^
  File "/home/airflow/.local/lib/python3.12/site-packages/minio/api.py", line 1707, in _put_object
    response = self._execute(
               ^^^^^^^^^^^^^^
  File "/home/airflow/.local/lib/python3.12/site-packages/minio/api.py", line 437, in _execute
    region = self._get_region(bucket_name)
             ^^^^^^^^^^^^^^^^^^^^^^^^^^^^^
  File "/home/airflow/.local/lib/python3.12/site-packages/minio/api.py", line 494, in _get_region
    response = self._url_open(
               ^^^^^^^^^^^^^^^
  File "/home/airflow/.local/lib/python3.12/site-packages/minio/api.py", line 302, in _url_open
    response = self._http.urlopen(
               ^^^^^^^^^^^^^^^^^^^
  File "/home/airflow/.local/lib/python3.12/site-packages/urllib3/poolmanager.py", line 443, in urlopen
    response = conn.urlopen(method, u.request_uri, **kw)
               ^^^^^^^^^^^^^^^^^^^^^^^^^^^^^^^^^^^^^^^^^
  File "/home/airflow/.local/lib/python3.12/site-packages/urllib3/connectionpool.py", line 873, in urlopen
    return self.urlopen(
           ^^^^^^^^^^^^^
  File "/home/airflow/.local/lib/python3.12/site-packages/urllib3/connectionpool.py", line 873, in urlopen
    return self.urlopen(
           ^^^^^^^^^^^^^
  File "/home/airflow/.local/lib/python3.12/site-packages/urllib3/connectionpool.py", line 873, in urlopen
    return self.urlopen(
           ^^^^^^^^^^^^^
  [Previous line repeated 2 more times]
  File "/home/airflow/.local/lib/python3.12/site-packages/urllib3/connectionpool.py", line 843, in urlopen
    retries = retries.increment(
              ^^^^^^^^^^^^^^^^^^
  File "/home/airflow/.local/lib/python3.12/site-packages/urllib3/util/retry.py", line 519, in increment
    raise MaxRetryError(_pool, url, reason) from reason  # type: ignore[arg-type]
    ^^^^^^^^^^^^^^^^^^^^^^^^^^^^^^^^^^^^^^^^^^^^^^^^^^^
urllib3.exceptions.MaxRetryError: HTTPConnectionPool(host='localhost', port=9000): Max retries exceeded with url: /drive-fetch?location= (Caused by NewConnectionError('<urllib3.connection.HTTPConnection object at 0x7f49d6fb63f0>: Failed to establish a new connection: [Errno 111] Connection refused'))
[2024-09-05T09:59:54.842+0000] {processor.py:927} WARNING - No viable dags retrieved from /opt/airflow/dags/download_dag.py
[2024-09-05T09:59:54.863+0000] {processor.py:208} INFO - Processing /opt/airflow/dags/download_dag.py took 13.933 seconds
[2024-09-05T10:00:25.136+0000] {processor.py:186} INFO - Started process (PID=336) to work on /opt/airflow/dags/download_dag.py
[2024-09-05T10:00:25.137+0000] {processor.py:914} INFO - Processing file /opt/airflow/dags/download_dag.py for tasks to queue
[2024-09-05T10:00:25.140+0000] {logging_mixin.py:190} INFO - [2024-09-05T10:00:25.140+0000] {dagbag.py:587} INFO - Filling up the DagBag from /opt/airflow/dags/download_dag.py
[2024-09-05T10:00:25.431+0000] {logging_mixin.py:190} INFO - [2024-09-05T10:00:25.430+0000] {__init__.py:49} INFO - file_cache is only supported with oauth2client<4.0.0
[2024-09-05T10:00:30.150+0000] {logging_mixin.py:190} INFO - Downloading cat1.png: 100%.
[2024-09-05T10:00:30.152+0000] {logging_mixin.py:190} INFO - [2024-09-05T10:00:30.152+0000] {connectionpool.py:870} WARNING - Retrying (Retry(total=4, connect=None, read=None, redirect=None, status=None)) after connection broken by 'NewConnectionError('<urllib3.connection.HTTPConnection object at 0x7f49d6f7be60>: Failed to establish a new connection: [Errno 111] Connection refused')': /drive-fetch?location=
[2024-09-05T10:00:30.554+0000] {logging_mixin.py:190} INFO - [2024-09-05T10:00:30.554+0000] {connectionpool.py:870} WARNING - Retrying (Retry(total=3, connect=None, read=None, redirect=None, status=None)) after connection broken by 'NewConnectionError('<urllib3.connection.HTTPConnection object at 0x7f49d6fb4920>: Failed to establish a new connection: [Errno 111] Connection refused')': /drive-fetch?location=
[2024-09-05T10:00:31.358+0000] {logging_mixin.py:190} INFO - [2024-09-05T10:00:31.357+0000] {connectionpool.py:870} WARNING - Retrying (Retry(total=2, connect=None, read=None, redirect=None, status=None)) after connection broken by 'NewConnectionError('<urllib3.connection.HTTPConnection object at 0x7f49d6fb4e60>: Failed to establish a new connection: [Errno 111] Connection refused')': /drive-fetch?location=
[2024-09-05T10:00:32.987+0000] {logging_mixin.py:190} INFO - [2024-09-05T10:00:32.986+0000] {connectionpool.py:870} WARNING - Retrying (Retry(total=1, connect=None, read=None, redirect=None, status=None)) after connection broken by 'NewConnectionError('<urllib3.connection.HTTPConnection object at 0x7f49d6fb54f0>: Failed to establish a new connection: [Errno 111] Connection refused')': /drive-fetch?location=
[2024-09-05T10:00:36.188+0000] {logging_mixin.py:190} INFO - [2024-09-05T10:00:36.188+0000] {connectionpool.py:870} WARNING - Retrying (Retry(total=0, connect=None, read=None, redirect=None, status=None)) after connection broken by 'NewConnectionError('<urllib3.connection.HTTPConnection object at 0x7f49d6fb5970>: Failed to establish a new connection: [Errno 111] Connection refused')': /drive-fetch?location=
[2024-09-05T10:00:36.244+0000] {logging_mixin.py:190} INFO - [2024-09-05T10:00:36.231+0000] {dagbag.py:386} ERROR - Failed to import: /opt/airflow/dags/download_dag.py
Traceback (most recent call last):
  File "/home/airflow/.local/lib/python3.12/site-packages/urllib3/connection.py", line 196, in _new_conn
    sock = connection.create_connection(
           ^^^^^^^^^^^^^^^^^^^^^^^^^^^^^
  File "/home/airflow/.local/lib/python3.12/site-packages/urllib3/util/connection.py", line 85, in create_connection
    raise err
  File "/home/airflow/.local/lib/python3.12/site-packages/urllib3/util/connection.py", line 73, in create_connection
    sock.connect(sa)
ConnectionRefusedError: [Errno 111] Connection refused

The above exception was the direct cause of the following exception:

Traceback (most recent call last):
  File "/home/airflow/.local/lib/python3.12/site-packages/urllib3/connectionpool.py", line 789, in urlopen
    response = self._make_request(
               ^^^^^^^^^^^^^^^^^^^
  File "/home/airflow/.local/lib/python3.12/site-packages/urllib3/connectionpool.py", line 495, in _make_request
    conn.request(
  File "/home/airflow/.local/lib/python3.12/site-packages/urllib3/connection.py", line 398, in request
    self.endheaders()
  File "/usr/local/lib/python3.12/http/client.py", line 1331, in endheaders
    self._send_output(message_body, encode_chunked=encode_chunked)
  File "/usr/local/lib/python3.12/http/client.py", line 1091, in _send_output
    self.send(msg)
  File "/usr/local/lib/python3.12/http/client.py", line 1035, in send
    self.connect()
  File "/home/airflow/.local/lib/python3.12/site-packages/urllib3/connection.py", line 236, in connect
    self.sock = self._new_conn()
                ^^^^^^^^^^^^^^^^
  File "/home/airflow/.local/lib/python3.12/site-packages/urllib3/connection.py", line 211, in _new_conn
    raise NewConnectionError(
urllib3.exceptions.NewConnectionError: <urllib3.connection.HTTPConnection object at 0x7f49d6fb6120>: Failed to establish a new connection: [Errno 111] Connection refused

The above exception was the direct cause of the following exception:

Traceback (most recent call last):
  File "/home/airflow/.local/lib/python3.12/site-packages/airflow/models/dagbag.py", line 382, in parse
    loader.exec_module(new_module)
  File "<frozen importlib._bootstrap_external>", line 995, in exec_module
  File "<frozen importlib._bootstrap>", line 488, in _call_with_frames_removed
  File "/opt/airflow/dags/download_dag.py", line 111, in <module>
    python_callable=download_to_minio(authenticate_gdrive(), FOLDER_ID),
                    ^^^^^^^^^^^^^^^^^^^^^^^^^^^^^^^^^^^^^^^^^^^^^^^^^^^
  File "/opt/airflow/dags/download_dag.py", line 78, in download_to_minio
    minio_client.put_object(
  File "/home/airflow/.local/lib/python3.12/site-packages/minio/api.py", line 1922, in put_object
    raise exc
  File "/home/airflow/.local/lib/python3.12/site-packages/minio/api.py", line 1868, in put_object
    return self._put_object(
           ^^^^^^^^^^^^^^^^^
  File "/home/airflow/.local/lib/python3.12/site-packages/minio/api.py", line 1707, in _put_object
    response = self._execute(
               ^^^^^^^^^^^^^^
  File "/home/airflow/.local/lib/python3.12/site-packages/minio/api.py", line 437, in _execute
    region = self._get_region(bucket_name)
             ^^^^^^^^^^^^^^^^^^^^^^^^^^^^^
  File "/home/airflow/.local/lib/python3.12/site-packages/minio/api.py", line 494, in _get_region
    response = self._url_open(
               ^^^^^^^^^^^^^^^
  File "/home/airflow/.local/lib/python3.12/site-packages/minio/api.py", line 302, in _url_open
    response = self._http.urlopen(
               ^^^^^^^^^^^^^^^^^^^
  File "/home/airflow/.local/lib/python3.12/site-packages/urllib3/poolmanager.py", line 443, in urlopen
    response = conn.urlopen(method, u.request_uri, **kw)
               ^^^^^^^^^^^^^^^^^^^^^^^^^^^^^^^^^^^^^^^^^
  File "/home/airflow/.local/lib/python3.12/site-packages/urllib3/connectionpool.py", line 873, in urlopen
    return self.urlopen(
           ^^^^^^^^^^^^^
  File "/home/airflow/.local/lib/python3.12/site-packages/urllib3/connectionpool.py", line 873, in urlopen
    return self.urlopen(
           ^^^^^^^^^^^^^
  File "/home/airflow/.local/lib/python3.12/site-packages/urllib3/connectionpool.py", line 873, in urlopen
    return self.urlopen(
           ^^^^^^^^^^^^^
  [Previous line repeated 2 more times]
  File "/home/airflow/.local/lib/python3.12/site-packages/urllib3/connectionpool.py", line 843, in urlopen
    retries = retries.increment(
              ^^^^^^^^^^^^^^^^^^
  File "/home/airflow/.local/lib/python3.12/site-packages/urllib3/util/retry.py", line 519, in increment
    raise MaxRetryError(_pool, url, reason) from reason  # type: ignore[arg-type]
    ^^^^^^^^^^^^^^^^^^^^^^^^^^^^^^^^^^^^^^^^^^^^^^^^^^^
urllib3.exceptions.MaxRetryError: HTTPConnectionPool(host='localhost', port=9000): Max retries exceeded with url: /drive-fetch?location= (Caused by NewConnectionError('<urllib3.connection.HTTPConnection object at 0x7f49d6fb6120>: Failed to establish a new connection: [Errno 111] Connection refused'))
[2024-09-05T10:00:36.246+0000] {processor.py:927} WARNING - No viable dags retrieved from /opt/airflow/dags/download_dag.py
[2024-09-05T10:00:36.277+0000] {processor.py:208} INFO - Processing /opt/airflow/dags/download_dag.py took 11.147 seconds
[2024-09-05T10:01:07.063+0000] {processor.py:186} INFO - Started process (PID=442) to work on /opt/airflow/dags/download_dag.py
[2024-09-05T10:01:07.064+0000] {processor.py:914} INFO - Processing file /opt/airflow/dags/download_dag.py for tasks to queue
[2024-09-05T10:01:07.067+0000] {logging_mixin.py:190} INFO - [2024-09-05T10:01:07.066+0000] {dagbag.py:587} INFO - Filling up the DagBag from /opt/airflow/dags/download_dag.py
[2024-09-05T10:01:07.322+0000] {logging_mixin.py:190} INFO - [2024-09-05T10:01:07.322+0000] {__init__.py:49} INFO - file_cache is only supported with oauth2client<4.0.0
[2024-09-05T10:01:11.494+0000] {logging_mixin.py:190} INFO - Downloading cat1.png: 100%.
[2024-09-05T10:01:11.498+0000] {logging_mixin.py:190} INFO - [2024-09-05T10:01:11.498+0000] {connectionpool.py:870} WARNING - Retrying (Retry(total=4, connect=None, read=None, redirect=None, status=None)) after connection broken by 'NewConnectionError('<urllib3.connection.HTTPConnection object at 0x7f499bdd4a10>: Failed to establish a new connection: [Errno 111] Connection refused')': /drive-fetch?location=
[2024-09-05T10:01:11.901+0000] {logging_mixin.py:190} INFO - [2024-09-05T10:01:11.901+0000] {connectionpool.py:870} WARNING - Retrying (Retry(total=3, connect=None, read=None, redirect=None, status=None)) after connection broken by 'NewConnectionError('<urllib3.connection.HTTPConnection object at 0x7f49d6fac6e0>: Failed to establish a new connection: [Errno 111] Connection refused')': /drive-fetch?location=
[2024-09-05T10:01:12.703+0000] {logging_mixin.py:190} INFO - [2024-09-05T10:01:12.702+0000] {connectionpool.py:870} WARNING - Retrying (Retry(total=2, connect=None, read=None, redirect=None, status=None)) after connection broken by 'NewConnectionError('<urllib3.connection.HTTPConnection object at 0x7f49d6facb90>: Failed to establish a new connection: [Errno 111] Connection refused')': /drive-fetch?location=
[2024-09-05T10:01:14.305+0000] {logging_mixin.py:190} INFO - [2024-09-05T10:01:14.304+0000] {connectionpool.py:870} WARNING - Retrying (Retry(total=1, connect=None, read=None, redirect=None, status=None)) after connection broken by 'NewConnectionError('<urllib3.connection.HTTPConnection object at 0x7f49d6fad460>: Failed to establish a new connection: [Errno 111] Connection refused')': /drive-fetch?location=
